Workbook

Sheet Ficha Contractual
B4: FICHA CONTRACTUAL
B5: Completar al inicio y actualizar ante cualquier modificación
B7: A. DATOS GENERALES DEL CRÉDITO
B8: Acreditado | C8: Red Girasol | D8: ID del Contrato | E8: 2025LP0007
B9: Razón Social | C9: RED GIRASOL SAPI DE CV | D9: Fecha de Firma | E9: 45715
B10: RFC | C10: RGI160414TR9 | D10: Fecha de 1ª disposición | E10: 45723
B11: Tipo de crédito | C11: Simple | D11: Fecha Vencimiento | E11: =EDATE(E10,C13)
B12: Monto original (MXN) | C12: 50000000 | D12: Sindicado (si aplica) | E12: No
B13: Plazo (meses) | C13: 36 | D13: Periodicidad de pago capital | E13: Mensual, Despues de 6 meses calendario a partir de la fecha de la primera Disposición
B14: Tasa base | C14: 0.205 | D14: Administrador Maestro | E14: CXC
B15: Tipo de tasa | C15: FIJA | D15: Número de fideicomiso | E15: Fideicomiso - 1403
B17: B. COVENANTS — LÍMITES Y NIVELES DE INCUMPLIMIENTO
B18: Nivel I: Ajustes generales en covenants |Nivel II: Ajuste de tasa +1% y aforo sube a 1.50x | Nivel III: Evento de aceleración
B19: Covenant | C19: Fórmula Modelo Monitoreo | D19: Base | E19: Post-ajuste Nivel I | F19: Post-ajuste Nivel II
B20: COVENANTS ESTÁNDAR (aplican a todos los créditos)
B21: Rentabilidad Operativa | C21: (Gtos venta + Gtos admin + Gtos operación) / (Intereses cobrados + Comisiones cobradas) | D21: 0.29 | E21: 0.25 | F21: 0.29
B22: Cobertura de Deuda | C22: Activos productivos / Pasivos totales [Activos prod. = Bancos + Inversiones + Cartera] | D22: 1 | E22: 1.15 | F22: 1.07
B23: Cartera Vencida Neta | C23: (Cartera Vencida − Reservas) / (Cartera Vigente + Cartera Vencida) | D23: 0.05 | E23: 0.05 | F23: 0.1
B24: Capitalización | C24: (Cartera crédito neta) / Capital Contable Elegible | D24: 0.11 | E24: 0.25 | F24: 0.2
B25: Estimación preventiva de riesgos | C25: Reservas / Cartera vencida | D25: 1 | E25: 1 | F25: 0.8
B26: Coeficiente de liquidez | C26: (Efectivo + Inversiones disponibles + Cobranza programada) / Vencimientos deuda programados | D26: 1.1x | E26: 1.1x | F26: 1.0x
B27: COVENANTS ESPECÍFICOS DEL CONTRATO
B28: IMOR 16 | C28: Cartera vencida 16m / Portafolio 16m | D28: ≤ 7.5% | E28: ≤ 7.5% | F28: TBA
B29: Índice de apalancamiento | C29: Pasivo Total/ Capital Contable Ajustado | D29: ≤ 6.0 | E29: ≤ 5.0 | F29: TBA
B30: Índice de apalancamiento ajustado | C30: Pasivo Total / Derechos de Cobro sobre Participaciones | D30: ≤ 90% | E30: ≤ 85% | F30: TBA
B31: Índice de capitalización | C31: Capital Contable Ajustado / Activo Total | D31: ≥ 13% | E31: ≥ 15% | F31: TBA
B32: Índice de cartera atrasada | C32: Cartera Atrasada / Valor del Portafolio | D32: ≤ 11% | E32: ≤ 11% | F32: TBA
B33: Índice de cartera vencida | C33: Cartera Vencida/ Valor del Portafolio | D33: ≤ 14% | E33: ≤ 14% | F33: TBA
B34: Índice de rendimiento | C34: Ingresos Agregados / Valor del Portafolio | D34: ≥ 28% | E34: ≥ 30% | F34: TBA
B35: Índice de rentabilidad | C35: Utilidad Neta / Valor del Portafolio | D35: ≥ -2% | E35: ≥ 0% | F35: TBA
B36: Aforo mínimo | C36: Ver fórmula completa en pestaña EEFF — CTO A | D36: ≥ 1.35x | E36: ≥ 1.50x* | F36: TBA
B37: * El aforo aplicable cambia a 1.50x ante incumplimiento del escenario base de IMOR 16 (IMOR 16 > 7.5%)
B39: C. EVENTOS DE INCUMPLIMIENTO — CONSECUENCIAS POR NIVEL
B40: Nivel | C40: Descripción | D40: Consecuencias contractuales | G40: Fecha de activación
B41: Nivel I | C41: Incumplimiento de Niveles I de los covenants | D41: Ajustes en las condiciones generales de los covenants base | G41: 45870
B42: Nivel II | C42: Incumplimiento de Niveles II de los covenants | D42: Ajuste de tasa de interés +1% sobre la tasa vigente. Aforo mínimo requerido sube a 1.50x. | G42: [Fecha]
B43: [Otro evento] | C43: [Describir el evento de incumplimiento adicional según el contrato] | D43: Se considera Evento de Aceleración. El acreditante puede exigir el pago anticipado de la totalidad del crédito. | G43: [Fecha]
B45: D. DEFINICIONES CONTRACTUALES CLAVE
B46: Concepto | C46: Definición resumida
B47: Cartera Vigente | C47: Créditos al corriente sin días de atraso.
...

Sheet Obligaciones
B4: OBLIGACIONES DE HACER Y NO HACER
B5: Documento informativo · Adjuntar al correo de solicitud del certificado de cumplimiento trimestral
B7: Este documento es un resumen ejecutivo sobre las obligaciones contractuales. Las obligaciones completas, sus definiciones y consecuencias de incumplimiento constan en el Contrato de Crédito respectivo.
B9: I. OBLIGACIONES DE HACER
B10: # | C10: Obligación | D10: Frecuencia / Plazo
B11: 1 | C11: Entregar balances y estados de resultados internos mensuales dentro de los 15 días posteriores al cierre de cada mes. | D11: Mensual — día 15
B12: 2 | C12: Proporcionar estados financieros auditados por un contador independiente dentro de los 120 días siguientes al cierre del ejercicio fiscal. | D12: Anual — Hasta 120 días
B13: 3 | C13: Entregar, junto con la información financiera, un certificado que acredite el cumplimiento de las obligaciones financieras y la inexistencia de incumplimientos. | D13: Mensual — día 15
B14: 4 | C14: Mantener una conexión en tiempo real entre sus sistemas contables y de cobranza con el Agente Administrativo y el Administrador Maestro. Que permitan al agente administrativo el acceso en todo momento a la información relacionada con los Derecho de Cobro Transmitidos | D14: Continua
B15: 5 | C15: Informar al Agente Administrativo sobre cualquier "Efecto Adverso de Importancia" o incumplimiento en un plazo máximo de 5 días hábiles. | D15: Inmediato al evento
B16: 6 | C16: Notificar sobre litigios cuya cuantía exceda los $5,000,000.00 MXN o multas impuestas por autoridades que superen dicho umbral. | D16: Inmediato al evento
B17: 7 | C17: Observar todas las leyes aplicables (especialmente LRITF, LTOSF y LPDUSF), así como presentar y pagar impuestos de manera oportuna. | D17: Continua
B18: 8 | C18: Realizar todos los actos necesarios para transmitir los Derechos de Cobro al Patrimonio del Fideicomiso y mantener vigente el Contrato de Factoraje. | D18: Continua
B19: 9 | C19: Mantener covenants financieros dentro de los límites del contrato. | D19: Mensual
B20: 10 | C20: Permitir al Agente Administrativo auditar sus bienes y libros con un aviso previo de 5 días. | D20: A Solicitud
B21: 11 | C21: Mantener en el fideicomiso el monto necesario para cubrir capital e intereses de la siguiente fecha de pago. | D21: Continua
B23: II. OBLIGACIONES DE NO HACER
B24: # | C24: Restricción | D24: Condiciones / Excepciones
B25: 1 | C25: No contratar nueva deuda, salvo la ya existente o aquella que no cause incumplimiento en sus obligaciones financieras. | D25: Con autorización escrita previa
B26: 2 | C26: No otorgar garantías a favor de terceros o constituir gravámenes sobre sus activos (especialmente sobre los que forman parte del patrimonio del fideicomiso). | D26: Ver covenants de capitalización y cobertura
B27: 3 | C27: No realizar fusiones, escisiones, disoluciones o ventas de activos sustanciales, ni cambiar la naturaleza de su negocio. | D27: Ver condiciones específicas del contrato
B28: 4 | C28: No distribuir dividendos si esto resulta en un incumplimiento de sus obligaciones bajo los Documentos del Crédito. | D28: Ver condiciones específicas del contrato
B29: 5 | C29: No realizar pagos extraordinarios de salarios o bonos a accionistas o funcionarios fuera de términos de mercado o que afecten los límites financieros. | D29: Ver condiciones específicas del contrato
B30: 6 | C30: No realizar un "Cambio de Control" (perder el control o bajar del 50% de los valores representativos de capital). | D30: Ver condiciones específicas del contrato
B31: 7 | C31: No modificar sus políticas de otorgamiento de crédito o los formatos de contratos con sus clientes (Contratos de Crédito Red Girasol) sin autorización. | D31: Ver condiciones específicas del contrato
B32: 8 | C32: No Participar en actividades ilícitas, producción de armas, tabaco, juegos de azar o aquellas que dañen el medio ambiente.
B33: 9 | C33: No permitir que otras obligaciones quirografarias tengan mayor preferencia de pago que el crédito presente.

Sheet Supuestos
A1: MODELO
A2: Inicio Crédito Syscap | B2: Dic-24 | C2: Cuentas por cobrar, neto | D2: 0
A3: Disp. Inicial | B3: 5000000 | C3: Pagos anticipados y otros activos, neto | D3: 1500000
A4: Cobranza | B4: 0.9 | C4: Propiedades, mobiliario y equipo, neto | D4: 200000
A5: Crecimiento Cartera | B5: 0.0075 | C5: CAPITALIZACIÓN | D5: 20000000
A6: Crecimiento Gastos | B6: 0.06 | C6: Castigo Tasa Activa | D6: 0.015
A8: CARTERA
A9: # de Registros | B9: =COUNT(#REF!) | C9: Días de Atraso Vencimientos | D9: 90
A10: Primer Crédito | B10: =MIN(#REF!)-DAY(MIN(#REF!))+1 | C10: Participación Histórica | D10: 0.01
A11: Tasa Activa Ponderada | B11: =SUMPRODUCT(#REF!,#REF!) | C11: Inicio Com. Apertura | D11: 44986
A12: Fecha LT | B12: 45657
A13: COMISIONES
A14: Tipo Producto | B14: Preoriginación | C14: Contratación | D14: Administración | E14: Notas
A15: Verde | B15: 0.02 | C15: 0.06 | D15: 0 | E15: Antes del 1 de Enero 2023
A16: Verde+ | B16: 0.02 | C16: 0 | D16: 0.01 | E16: Entre 01/01/23 y 01/01/24 - SOBRE EL SALDO INSOLUTO
A17: Crédito Automotriz | B17: 0.02 | C17: 0.015 | D17: 0.011 | E17: A partir del 2024
A18: Crédito Personal | B18: 0.02 | C18: 0.02 | D18: 0.0135 | E18: A partir del 2024
A19: Crédito PYME | B19: 0.02 | C19: 0.015 | D19: 0.011 | E19: A partir del 2024
A20: Crédito Solar | B20: 0.02 | C20: 0.01 | D20: 0.0085 | E20: A partir del 2024
A21: Comisión Éxito Vieja | B21: 0.02 | E21: Sobre cobranza total (intereses y amortizaciones)
A22: Comisión Éxito Nueva | B22: 0.1 | C22: Desde | D22: 45536 | E22: Sobre intereses a partir de Sep. 2024

Sheet Crédito Syscap
A1: Mes | B1: Saldo Inicial | C1: Disposiciones | D1: Pago | E1: Interés | F1: Amortización | G1: Saldo Final | H1: Comisión Estr | I1: Comisión Admin | J1: Total Comisiones
A2: 0 | B2: 0 | C2: 20000000
A3: 1 | B3: =C2 | C3: 15000000 | D3: =IF(A3<=$B$45, E3, IF(B3>0, B3*(($B$40/12)/(1-(1+($B$40/12))^(-($B$44-A3+1)))), 0)) | E3: =B3*$B$40/12 | F3: =IF(A3<=$B$45, 0, D3-E3) | G3: =B3-F3 | H3: =C2*$B$47 | I3: =($B$42*$B$48/12) | J3: =H3+I3
A4: 2 | B4: =G3+C3 | C4: 15000000 | D4: =IF(A4<=$B$45, E4, IF(B4>0, B4*(($B$40/12)/(1-(1+($B$40/12))^(-($B$44-A4+1)))), 0)) | E4: =B4*$B$40/12 | F4: =IF(A4<=$B$45, 0, D4-E4) | G4: =B4-F4 | H4: =C3*$B$47 | I4: =($B$42*$B$48/12) | J4: =H4+I4
A5: 3 | B5: =G4+C4 | C5: 0 | D5: =IF(A5<=$B$45, E5, IF(B5>0, B5*(($B$40/12)/(1-(1+($B$40/12))^(-($B$44-A5+1)))), 0)) | E5: =B5*$B$40/12 | F5: =IF(A5<=$B$45, 0, D5-E5) | G5: =B5-F5 | H5: =C4*$B$47 | I5: =($B$42*$B$48/12) | J5: =H5+I5
A6: 4 | B6: =G5+C5 | C6: 0 | D6: =IF(A6<=$B$45, E6, IF(B6>0, B6*(($B$40/12)/(1-(1+($B$40/12))^(-($B$44-A6+1)))), 0)) | E6: =B6*$B$40/12 | F6: =IF(A6<=$B$45, 0, D6-E6) | G6: =B6-F6 | H6: =C5*$B$47 | I6: =($B$42*$B$48/12) | J6: =H6+I6
A7: 5 | B7: =G6+C6 | C7: 0 | D7: =IF(A7<=$B$45, E7, IF(B7>0, B7*(($B$40/12)/(1-(1+($B$40/12))^(-($B$44-A7+1)))), 0)) | E7: =B7*$B$40/12 | F7: =IF(A7<=$B$45, 0, D7-E7) | G7: =B7-F7 | H7: =C6*$B$47 | I7: =($B$42*$B$48/12) | J7: =H7+I7
A8: 6 | B8: =G7+C7 | C8: 0 | D8: =IF(A8<=$B$45, E8, IF(B8>0, B8*(($B$40/12)/(1-(1+($B$40/12))^(-($B$44-A8+1)))), 0)) | E8: =B8*$B$40/12 | F8: =IF(A8<=$B$45, 0, D8-E8) | G8: =B8-F8 | H8: =C7*$B$47 | I8: =($B$42*$B$48/12) | J8: =H8+I8
A9: 7 | B9: =G8+C8 | C9: 0 | D9: =IF(A9<=$B$45, E9, IF(B9>0, B9*(($B$40/12)/(1-(1+($B$40/12))^(-($B$44-A9+1)))), 0)) | E9: =B9*$B$40/12 | F9: =IF(A9<=$B$45, 0, D9-E9) | G9: =B9-F9 | H9: =C8*$B$47 | I9: =($B$42*$B$48/12) | J9: =H9+I9
A10: 8 | B10: =G9+C9 | C10: 0 | D10: =IF(A10<=$B$45, E10, IF(B10>0, B10*(($B$40/12)/(1-(1+($B$40/12))^(-($B$44-A10+1)))), 0)) | E10: =B10*$B$40/12 | F10: =IF(A10<=$B$45, 0, D10-E10) | G10: =B10-F10 | H10: =C9*$B$47 | I10: =($B$42*$B$48/12) | J10: =H10+I10
A11: 9 | B11: =G10+C10 | C11: 0 | D11: =IF(A11<=$B$45, E11, IF(B11>0, B11*(($B$40/12)/(1-(1+($B$40/12))^(-($B$44-A11+1)))), 0)) | E11: =B11*$B$40/12 | F11: =IF(A11<=$B$45, 0, D11-E11) | G11: =B11-F11 | H11: =C10*$B$47 | I11: =($B$42*$B$48/12) | J11: =H11+I11
A12: 10 | B12: =G11+C11 | D12: =IF(A12<=$B$45, E12, IF(B12>0, B12*(($B$40/12)/(1-(1+($B$40/12))^(-($B$44-A12+1)))), 0)) | E12: =B12*$B$40/12 | F12: =IF(A12<=$B$45, 0, D12-E12) | G12: =B12-F12 | H12: =C11*$B$47 | I12: =($B$42*$B$48/12) | J12: =H12+I12
A13: 11 | B13: =G12+C12 | D13: =IF(A13<=$B$45, E13, IF(B13>0, B13*(($B$40/12)/(1-(1+($B$40/12))^(-($B$44-A13+1)))), 0)) | E13: =B13*$B$40/12 | F13: =IF(A13<=$B$45, 0, D13-E13) | G13: =B13-F13 | H13: =C12*$B$47 | I13: =($B$42*$B$48/12) | J13: =H13+I13
A14: 12 | B14: =G13+C13 | D14: =IF(A14<=$B$45, E14, IF(B14>0, B14*(($B$40/12)/(1-(1+($B$40/12))^(-($B$44-A14+1)))), 0)) | E14: =B14*$B$40/12 | F14: =IF(A14<=$B$45, 0, D14-E14) | G14: =B14-F14 | H14: =C13*$B$47 | I14: =($B$42*$B$48/12) | J14: =H14+I14
A15: 13 | B15: =G14+C14 | D15: =IF(A15<=$B$45, E15, IF(B15>0, B15*(($B$40/12)/(1-(1+($B$40/12))^(-($B$44-A15+1)))), 0)) | E15: =B15*$B$40/12 | F15: =IF(A15<=$B$45, 0, D15-E15) | G15: =B15-F15 | H15: =C14*$B$47 | I15: =($B$42*$B$48/12) | J15: =H15+I15
A16: 14 | B16: =G15+C15 | D16: =IF(A16<=$B$45, E16, IF(B16>0, B16*(($B$40/12)/(1-(1+($B$40/12))^(-($B$44-A16+1)))), 0)) | E16: =B16*$B$40/12 | F16: =IF(A16<=$B$45, 0, D16-E16) | G16: =B16-F16 | H16: =C15*$B$47 | I16: =($B$42*$B$48/12) | J16: =H16+I16
A17: 15 | B17: =G16+C16 | D17: =IF(A17<=$B$45, E17, IF(B17>0, B17*(($B$40/12)/(1-(1+($B$40/12))^(-($B$44-A17+1)))), 0)) | E17: =B17*$B$40/12 | F17: =IF(A17<=$B$45, 0, D17-E17) | G17: =B17-F17 | H17: =C16*$B$47 | I17: =($B$42*$B$48/12) | J17: =H17+I17
A18: 16 | B18: =G17+C17 | D18: =IF(A18<=$B$45, E18, IF(B18>0, B18*(($B$40/12)/(1-(1+($B$40/12))^(-($B$44-A18+1)))), 0)) | E18: =B18*$B$40/12 | F18: =IF(A18<=$B$45, 0, D18-E18) | G18: =B18-F18 | H18: =C17*$B$47 | I18: =($B$42*$B$48/12) | J18: =H18+I18
A19: 17 | B19: =G18+C18 | D19: =IF(A19<=$B$45, E19, IF(B19>0, B19*(($B$40/12)/(1-(1+($B$40/12))^(-($B$44-A19+1)))), 0)) | E19: =B19*$B$40/12 | F19: =IF(A19<=$B$45, 0, D19-E19) | G19: =B19-F19 | H19: =C18*$B$47 | I19: =($B$42*$B$48/12) | J19: =H19+I19
A20: 18 | B20: =G19+C19 | D20: =IF(A20<=$B$45, E20, IF(B20>0, B20*(($B$40/12)/(1-(1+($B$40/12))^(-($B$44-A20+1)))), 0)) | E20: =B20*$B$40/12 | F20: =IF(A20<=$B$45, 0, D20-E20) | G20: =B20-F20 | H20: =C19*$B$47 | I20: =($B$42*$B$48/12) | J20: =H20+I20
A21: 19 | B21: =G20+C20 | D21: =IF(A21<=$B$45, E21, IF(B21>0, B21*(($B$40/12)/(1-(1+($B$40/12))^(-($B$44-A21+1)))), 0)) | E21: =B21*$B$40/12 | F21: =IF(A21<=$B$45, 0, D21-E21) | G21: =B21-F21 | H21: =C20*$B$47 | I21: =($B$42*$B$48/12) | J21: =H21+I21
A22: 20 | B22: =G21+C21 | D22: =IF(A22<=$B$45, E22, IF(B22>0, B22*(($B$40/12)/(1-(1+($B$40/12))^(-($B$44-A22+1)))), 0)) | E22: =B22*$B$40/12 | F22: =IF(A22<=$B$45, 0, D22-E22) | G22: =B22-F22 | H22: =C21*$B$47 | I22: =($B$42*$B$48/12) | J22: =H22+I22
A23: 21 | B23: =G22+C22 | D23: =IF(A23<=$B$45, E23, IF(B23>0, B23*(($B$40/12)/(1-(1+($B$40/12))^(-($B$44-A23+1)))), 0)) | E23: =B23*$B$40/12 | F23: =IF(A23<=$B$45, 0, D23-E23) | G23: =B23-F23 | H23: =C22*$B$47 | I23: =($B$42*$B$48/12) | J23: =H23+I23
... A38: 36 | B38: =G37+C37 | D38: =IF(A38<=$B$45, E38, IF(B38>0, B38*(($B$40/12)/(1-(1+($B$40/12))^(-($B$44-A38+1)))), 0)) | E38: =B38*$B$40/12 | F38: =IF(A38<=$B$45, 0, D38-E38) | G38: =B38-F38 | H38: =C37*$B$47 | I38: =($B$42*$B$48/12) | J38: =H38+I38
A40: Tasa | B40: 0.21
A41: Monto Disposiciones | B41: 10000000
A42: Saldo Total Línea | B42: 50000000
A43: Cantidad de Disp. | B43: 2
A44: Plazo | B44: 36
A45: Gracia de Capital | B45: 6
A46: Gastos Notariales | B46: 550000
A47: Comisión Estr. | B47: 0.02
A48: Comisión Admin. | B48: 0.005

Sheet Monitoreo
B2: IMOR 16
B3: 45657 | C3: =EOMONTH(B3,1) | D3: =EOMONTH(C3,1) | E3: =EOMONTH(D3,1) | F3: =EOMONTH(E3,1) | G3: =EOMONTH(F3,1) | H3: =EOMONTH(G3,1) | I3: =EOMONTH(H3,1) | J3: =EOMONTH(I3,1) | ... BJ3: =EOMONTH(BI3,1)
A4: RL | B4: ='Efs Real'!L69 | D4: ='Efs Real'!N69 | E4: ='Efs Real'!O69 | F4: ='Efs Real'!P69 | G4: ='Efs Real'!Q69 | H4: ='Efs Real'!R69 | I4: ='Efs Real'!S69 | J4: ='Efs Real'!T69 | K4: ='Efs Real'!U69 | ... P4: ='Efs Real'!Z69
A5: MAX | B5: 0.075 | C5: 0.075 | D5: 0.075 | E5: 0.075 | F5: 0.075 | G5: 0.075 | H5: 0.075 | I5: 0.075 | J5: 0.075 | K5: 0.075 | L5: 0.075 | M5: 0.075 | N5: 0.075 | O5: 0.075 | P5: 0.075 | Q5: 0.075 | R5: 0.075 | S5: 0.075 | T5: 0.075 | U5: 0.075 | V5: 0.075 | W5: 0.075 | X5: 0.075 | Y5: 0.075 | Z5: 0.075 | AA5: 0.075 | AB5: 0.075 | AC5: 0.075 | AD5: 0.075 | AE5: 0.075 | AF5: 0.075 | AG5: 0.075 | AH5: 0.075 | AI5: 0.075 | AJ5: 0.075 | AK5: 0.075 | AL5: 0.075 | AM5: 0.075 | AN5: 0.075 | AO5: 0.075 | AP5: 0.075 | AQ5: 0.075 | AR5: 0.075 | AS5: 0.075 | AT5: 0.075 | AU5: 0.075 | AV5: 0.075 | AW5: 0.075 | AX5: 0.075 | AY5: 0.075 | AZ5: 0.075 | BA5: 0.075 | BB5: 0.075 | BC5: 0.075 | BD5: 0.075 | BE5: 0.075 | BF5: 0.075 | BG5: 0.075 | BH5: 0.075 | BI5: 0.075 | BJ5: 0.075
B7: Indice de apalancamiento
B8: 45657 | C8: =EOMONTH(B8,1) | D8: =EOMONTH(C8,1) | E8: =EOMONTH(D8,1) | F8: =EOMONTH(E8,1) | G8: =EOMONTH(F8,1) | H8: =EOMONTH(G8,1) | I8: =EOMONTH(H8,1) | J8: =EOMONTH(I8,1) | ... BJ8: =EOMONTH(BI8,1)
A9: OG | B9: ='Efs OG'!CS84 | C9: ='Efs OG'!CT84 | D9: ='Efs OG'!CU84 | E9: ='Efs OG'!CV84 | F9: ='Efs OG'!CW84 | G9: ='Efs OG'!CX84 | H9: ='Efs OG'!CY84 | I9: ='Efs OG'!CZ84 | ... BJ9: ='Efs OG'!FA84
A10: RL | B10: ='Efs Real'!L57 | C10: ='Efs Real'!M57 | D10: ='Efs Real'!N57 | E10: ='Efs Real'!O57 | F10: ='Efs Real'!P57 | G10: ='Efs Real'!Q57 | H10: ='Efs Real'!R57 | I10: ='Efs Real'!S57 | ... P10: ='Efs Real'!Z57
A11: MAX | B11: 6 | C11: 6 | D11: 6 | E11: 6 | F11: 6 | G11: 6 | H11: 6 | I11: 6 | J11: 5 | K11: 5 | L11: 5 | M11: 5 | N11: 5 | O11: 5 | P11: 5 | Q11: 5 | R11: 5 | S11: 5 | T11: 5 | U11: 5 | V11: 5 | W11: 5 | X11: 5 | Y11: 5 | Z11: 5 | AA11: 5 | AB11: 5 | AC11: 5 | AD11: 5 | AE11: 5 | AF11: 5 | AG11: 5 | AH11: 5 | AI11: 5 | AJ11: 5 | AK11: 5 | AL11: 5 | AM11: 5 | AN11: 5 | AO11: 5 | AP11: 5 | AQ11: 5 | AR11: 5 | AS11: 5 | AT11: 5 | AU11: 5 | AV11: 5 | AW11: 5 | AX11: 5 | AY11: 5 | AZ11: 5 | BA11: 5 | BB11: 5 | BC11: 5 | BD11: 5 | BE11: 5 | BF11: 5 | BG11: 5 | BH11: 5 | BI11: 5 | BJ11: 5
A13: =IFERROR(__xludf.DUMMYFUNCTION("IMPORTRANGE(""https://docs.google.com/spreadsheets/d/1RNG9c9ku9IgXbqzh4Ng5a6f84xmyVPd-/edit?usp=sharing&ouid=116612639875179195240&rtpof=true&sd=true"",""Efs Real!B1"")"),"#REF!") | B13: Indice de apalancamiento ajustado
A14: =IFERROR(__xludf.DUMMYFUNCTION("IMPORTRANGE(""https://docs.google.com/spreadsheets/d/1RNG9c9ku9IgXbqzh4Ng5a6f84xmyVPd-/edit?gid=1965519997#gid=1965519997"",""Efs Real!B:B"")"),"#REF!") | B14: 45657 | C14: =EOMONTH(B14,1) | D14: =EOMONTH(C14,1) | E14: =EOMONTH(D14,1) | F14: =EOMONTH(E14,1) | G14: =EOMONTH(F14,1) | H14: =EOMONTH(G14,1) | I14: =EOMONTH(H14,1) | J14: =EOMONTH(I14,1) | ... BJ14: =EOMONTH(BI14,1)
A15: OG | B15: ='Efs OG'!CS85 | C15: ='Efs OG'!CT85 | D15: ='Efs OG'!CU85 | E15: ='Efs OG'!CV85 | F15: ='Efs OG'!CW85 | G15: ='Efs OG'!CX85 | H15: ='Efs OG'!CY85 | I15: ='Efs OG'!CZ85 | ... BJ15: ='Efs OG'!FA85
A16: RL | B16: ='Efs Real'!L58 | C16: ='Efs Real'!M58 | D16: ='Efs Real'!N58 | E16: ='Efs Real'!O58 | F16: ='Efs Real'!P58 | G16: ='Efs Real'!Q58 | H16: ='Efs Real'!R58 | I16: ='Efs Real'!S58 | ... P16: ='Efs Real'!Z58
A17: MAX | B17: 0.9 | C17: 0.9 | D17: 0.9 | E17: 0.9 | F17: 0.9 | G17: 0.9 | H17: 0.9 | I17: 0.9 | J17: 0.85 | K17: 0.85 | L17: 0.85 | M17: 0.85 | N17: 0.85 | O17: 0.85 | P17: 0.85 | Q17: 0.85 | R17: 0.85 | S17: 0.85 | T17: 0.85 | U17: 0.85 | V17: 0.85 | W17: 0.85 | X17: 0.85 | Y17: 0.85 | Z17: 0.85 | AA17: 0.85 | AB17: 0.85 | AC17: 0.85 | AD17: 0.85 | AE17: 0.85 | AF17: 0.85 | AG17: 0.85 | AH17: 0.85 | AI17: 0.85 | AJ17: 0.85 | AK17: 0.85 | AL17: 0.85 | AM17: 0.85 | AN17: 0.85 | AO17: 0.85 | AP17: 0.85 | AQ17: 0.85 | AR17: 0.85 | AS17: 0.85 | AT17: 0.85 | AU17: 0.85 | AV17: 0.85 | AW17: 0.85 | AX17: 0.85 | AY17: 0.85 | AZ17: 0.85 | BA17: 0.85 | BB17: 0.85 | BC17: 0.85 | BD17: 0.85 | BE17: 0.85 | BF17: 0.85 | BG17: 0.85 | BH17: 0.85 | BI17: 0.85 | BJ17: 0.85
B19: Indice de capitalizacion
B20: 45657 | C20: =EOMONTH(B20,1) | D20: =EOMONTH(C20,1) | E20: =EOMONTH(D20,1) | F20: =EOMONTH(E20,1) | G20: =EOMONTH(F20,1) | H20: =EOMONTH(G20,1) | I20: =EOMONTH(H20,1) | J20: =EOMONTH(I20,1) | ... BJ20: =EOMONTH(BI20,1)
A21: OG | B21: ='Efs OG'!CS83 | C21: ='Efs OG'!CT83 | D21: ='Efs OG'!CU83 | E21: ='Efs OG'!CV83 | F21: ='Efs OG'!CW83 | G21: ='Efs OG'!CX83 | H21: ='Efs OG'!CY83 | I21: ='Efs OG'!CZ83 | ... BJ21: ='Efs OG'!FA83
A22: RL | B22: ='Efs Real'!L60 | C22: ='Efs Real'!M60 | D22: ='Efs Real'!N60 | E22: ='Efs Real'!O60 | F22: ='Efs Real'!P60 | G22: ='Efs Real'!Q60 | H22: ='Efs Real'!R60 | I22: ='Efs Real'!S60 | ... P22: ='Efs Real'!Z60
A23: MIN | B23: 0.13 | C23: 0.13 | D23: 0.13 | E23: 0.13 | F23: 0.13 | G23: 0.13 | H23: 0.13 | I23: 0.13 | J23: 0.15 | K23: 0.15 | L23: 0.15 | M23: 0.15 | N23: 0.15 | O23: 0.15 | P23: 0.15 | Q23: 0.15 | R23: 0.15 | S23: 0.15 | T23: 0.15 | U23: 0.15 | V23: 0.15 | W23: 0.15 | X23: 0.15 | Y23: 0.15 | Z23: 0.15 | AA23: 0.15 | AB23: 0.15 | AC23: 0.15 | AD23: 0.15 | AE23: 0.15 | AF23: 0.15 | AG23: 0.15 | AH23: 0.15 | AI23: 0.15 | AJ23: 0.15 | AK23: 0.15 | AL23: 0.15 | AM23: 0.15 | AN23: 0.15 | AO23: 0.15 | AP23: 0.15 | AQ23: 0.15 | AR23: 0.15 | AS23: 0.15 | AT23: 0.15 | AU23: 0.15 | AV23: 0.15 | AW23: 0.15 | AX23: 0.15 | AY23: 0.15 | AZ23: 0.15 | BA23: 0.15 | BB23: 0.15 | BC23: 0.15 | BD23: 0.15 | BE23: 0.15 | BF23: 0.15 | BG23: 0.15 | BH23: 0.15 | BI23: 0.15 | BJ23: 0.15
B25: Indice de cartera atrasada
B26: 45657 | C26: =EOMONTH(B26,1) | D26: =EOMONTH(C26,1) | E26: =EOMONTH(D26,1) | F26: =EOMONTH(E26,1) | G26: =EOMONTH(F26,1) | H26: =EOMONTH(G26,1) | I26: =EOMONTH(H26,1) | J26: =EOMONTH(I26,1) | ... BJ26: =EOMONTH(BI26,1)
A27: RL | B27: ='Efs Real'!L79 | D27: ='Efs Real'!N79 | E27: ='Efs Real'!O79 | F27: ='Efs Real'!P79 | G27: ='Efs Real'!Q79 | H27: ='Efs Real'!R79 | I27: ='Efs Real'!S79 | J27: ='Efs Real'!T79 | K27: ='Efs Real'!U79 | ... P27: ='Efs Real'!Z79
A28: MAX | B28: 0.11 | C28: 0.11 | D28: 0.11 | E28: 0.11 | F28: 0.11 | G28: 0.11 | H28: 0.11 | I28: 0.11 | J28: 0.11 | K28: 0.11 | L28: 0.11 | M28: 0.11 | N28: 0.11 | O28: 0.11 | P28: 0.11 | Q28: 0.11 | R28: 0.11 | S28: 0.11 | T28: 0.11 | U28: 0.11 | V28: 0.11 | W28: 0.11 | X28: 0.11 | Y28: 0.11 | Z28: 0.11 | AA28: 0.11 | AB28: 0.11 | AC28: 0.11 | AD28: 0.11 | AE28: 0.11 | AF28: 0.11 | AG28: 0.11 | AH28: 0.11 | AI28: 0.11 | AJ28: 0.11 | AK28: 0.11 | AL28: 0.11 | AM28: 0.11 | AN28: 0.11 | AO28: 0.11 | AP28: 0.11 | AQ28: 0.11 | AR28: 0.11 | AS28: 0.11 | AT28: 0.11 | AU28: 0.11 | AV28: 0.11 | AW28: 0.11 | AX28: 0.11 | AY28: 0.11 | AZ28: 0.11 | BA28: 0.11 | BB28: 0.11 | BC28: 0.11 | BD28: 0.11 | BE28: 0.11 | BF28: 0.11 | BG28: 0.11 | BH28: 0.11 | BI28: 0.11 | BJ28: 0.11
B30: Indice de cartera vencida
B31: 45657 | C31: =EOMONTH(B31,1) | D31: =EOMONTH(C31,1) | E31: =EOMONTH(D31,1) | F31: =EOMONTH(E31,1) | G31: =EOMONTH(F31,1) | H31: =EOMONTH(G31,1) | I31: =EOMONTH(H31,1) | J31: =EOMONTH(I31,1) | ... BJ31: =EOMONTH(BI31,1)
A32: RL | B32: ='Efs Real'!L78 | D32: ='Efs Real'!N78 | E32: ='Efs Real'!O78 | F32: ='Efs Real'!P78 | G32: ='Efs Real'!Q78 | H32: ='Efs Real'!R78 | I32: ='Efs Real'!S78 | J32: ='Efs Real'!T78 | K32: ='Efs Real'!U78 | ... P32: ='Efs Real'!Z78
A33: MAX | B33: 0.14 | C33: 0.14 | D33: 0.14 | E33: 0.14 | F33: 0.14 | G33: 0.14 | H33: 0.14 | I33: 0.14 | J33: 0.14 | K33: 0.14 | L33: 0.14 | M33: 0.14 | N33: 0.14 | O33: 0.14 | P33: 0.14 | Q33: 0.14 | R33: 0.14 | S33: 0.14 | T33: 0.14 | U33: 0.14 | V33: 0.14 | W33: 0.14 | X33: 0.14 | Y33: 0.14 | Z33: 0.14 | AA33: 0.14 | AB33: 0.14 | AC33: 0.14 | AD33: 0.14 | AE33: 0.14 | AF33: 0.14 | AG33: 0.14 | AH33: 0.14 | AI33: 0.14 | AJ33: 0.14 | AK33: 0.14 | AL33: 0.14 | AM33: 0.14 | AN33: 0.14 | AO33: 0.14 | AP33: 0.14 | AQ33: 0.14 | AR33: 0.14 | AS33: 0.14 | AT33: 0.14 | AU33: 0.14 | AV33: 0.14 | AW33: 0.14 | AX33: 0.14 | AY33: 0.14 | AZ33: 0.14 | BA33: 0.14 | BB33: 0.14 | BC33: 0.14 | BD33: 0.14 | BE33: 0.14 | BF33: 0.14 | BG33: 0.14 | BH33: 0.14 | BI33: 0.14 | BJ33: 0.14
B35: Indice de rendimiento
B36: 45657 | C36: =EOMONTH(B36,1) | D36: =EOMONTH(C36,1) | E36: =EOMONTH(D36,1) | F36: =EOMONTH(E36,1) | G36: =EOMONTH(F36,1) | H36: =EOMONTH(G36,1) | I36: =EOMONTH(H36,1) | J36: =EOMONTH(I36,1) | ... BJ36: =EOMONTH(BI36,1)
A37: OG | B37: ='Efs OG'!CS86 | C37: ='Efs OG'!CT86 | D37: ='Efs OG'!CU86 | E37: ='Efs OG'!CV86 | F37: ='Efs OG'!CW86 | G37: ='Efs OG'!CX86 | H37: ='Efs OG'!CY86 | I37: ='Efs OG'!CZ86 | ... BJ37: ='Efs OG'!FA86
A38: RL | B38: ='Efs Real'!L61 | D38: ='Efs Real'!N61 | E38: ='Efs Real'!O61 | F38: ='Efs Real'!P61 | G38: ='Efs Real'!Q61 | H38: ='Efs Real'!R61 | I38: ='Efs Real'!S61 | J38: ='Efs Real'!T61 | K38: ='Efs Real'!U61 | ... P38: ='Efs Real'!Z61
A39: MIN | B39: 0.28 | C39: 0.28 | D39: 0.28 | E39: 0.28 | F39: 0.28 | G39: 0.28 | H39: 0.28 | I39: 0.28 | J39: 0.3 | K39: 0.3 | L39: 0.3 | M39: 0.3 | N39: 0.3 | O39: 0.3 | P39: 0.3 | Q39: 0.3 | R39: 0.3 | S39: 0.3 | T39: 0.3 | U39: 0.3 | V39: 0.3 | W39: 0.3 | X39: 0.3 | Y39: 0.3 | Z39: 0.3 | AA39: 0.3 | AB39: 0.3 | AC39: 0.3 | AD39: 0.3 | AE39: 0.3 | AF39: 0.3 | AG39: 0.3 | AH39: 0.3 | AI39: 0.3 | AJ39: 0.3 | AK39: 0.3 | AL39: 0.3 | AM39: 0.3 | AN39: 0.3 | AO39: 0.3 | AP39: 0.3 | AQ39: 0.3 | AR39: 0.3 | AS39: 0.3 | AT39: 0.3 | AU39: 0.3 | AV39: 0.3 | AW39: 0.3 | AX39: 0.3 | AY39: 0.3 | AZ39: 0.3 | BA39: 0.3 | BB39: 0.3 | BC39: 0.3 | BD39: 0.3 | BE39: 0.3 | BF39: 0.3 | BG39: 0.3 | BH39: 0.3 | BI39: 0.3 | BJ39: 0.3
B41: Indice rentabilidad
B42: 45657 | C42: =EOMONTH(B42,1) | D42: =EOMONTH(C42,1) | E42: =EOMONTH(D42,1) | F42: =EOMONTH(E42,1) | G42: =EOMONTH(F42,1) | H42: =EOMONTH(G42,1) | I42: =EOMONTH(H42,1) | J42: =EOMONTH(I42,1) | ... BJ42: =EOMONTH(BI42,1)
A43: OG | B43: ='Efs OG'!CS87 | C43: ='Efs OG'!CT87 | D43: ='Efs OG'!CU87 | E43: ='Efs OG'!CV87 | F43: ='Efs OG'!CW87 | G43: ='Efs OG'!CX87 | H43: ='Efs OG'!CY87 | I43: ='Efs OG'!CZ87 | ... BJ43: ='Efs OG'!FA87
A44: RL | B44: ='Efs Real'!L62 | D44: ='Efs Real'!N62 | E44: ='Efs Real'!O62 | F44: ='Efs Real'!P62 | G44: ='Efs Real'!Q62 | H44: ='Efs Real'!R62 | I44: ='Efs Real'!S62 | J44: ='Efs Real'!T62 | K44: ='Efs Real'!U62 | ... P44: ='Efs Real'!Z62
A45: MIN | B45: -0.02 | C45: -0.02 | D45: -0.02 | E45: -0.02 | F45: -0.02 | G45: -0.02 | H45: -0.02 | I45: -0.02 | J45: 0 | K45: 0 | L45: 0 | M45: 0 | N45: 0 | O45: 0 | P45: 0 | Q45: 0 | R45: 0 | S45: 0 | T45: 0 | U45: 0 | V45: 0 | W45: 0 | X45: 0 | Y45: 0 | Z45: 0 | AA45: 0 | AB45: 0 | AC45: 0 | AD45: 0 | AE45: 0 | AF45: 0 | AG45: 0 | AH45: 0 | AI45: 0 | AJ45: 0 | AK45: 0 | AL45: 0 | AM45: 0 | AN45: 0 | AO45: 0 | AP45: 0 | AQ45: 0 | AR45: 0 | AS45: 0 | AT45: 0 | AU45: 0 | AV45: 0 | AW45: 0 | AX45: 0 | AY45: 0 | AZ45: 0 | BA45: 0 | BB45: 0 | BC45: 0 | BD45: 0 | BE45: 0 | BF45: 0 | BG45: 0 | BH45: 0 | BI45: 0 | BJ45: 0
B48: 45657 | C48: =EOMONTH(B48,1) | D48: =EOMONTH(C48,1) | E48: =EOMONTH(D48,1) | F48: =EOMONTH(E48,1) | G48: =EOMONTH(F48,1) | H48: =EOMONTH(G48,1) | I48: =EOMONTH(H48,1) | J48: =EOMONTH(I48,1) | ... BJ48: =EOMONTH(BI48,1)
A49: Aforo mínimo | B49: =IF(B4>7.5%, 1.5, 1.35) | C49: =IF(C4>7.5%, 1.5, 1.35) | D49: =IF(D4>7.5%, 1.5, 1.35) | E49: =IF(E4>7.5%, 1.5, 1.35) | F49: =IF(F4>7.5%, 1.5, 1.35) | G49: =IF(G4>7.5%, 1.5, 1.35) | H49: =IF(H4>7.5%, 1.5, 1.35) | I49: =IF(I4>7.5%, 1.5, 1.35) | J49: =IF(J4>7.5%, 1.5, 1.35) | K49: =IF(J4>7.5%, 1.5, 1.35) | L49: =IF(L4>7.5%, 1.5, 1.35) | M49: =IF(M4>7.5%, 1.5, 1.35) | N49: =IF(N4>7.5%, 1.5, 1.35) | O49: =IF(O4>7.5%, 1.5, 1.35) | P49: =IF(P4>7.5%, 1.5, 1.35) | Q49: =IF(Q4>7.5%, 1.5, 1.35) | R49: =IF(R4>7.5%, 1.5, 1.35) | S49: =IF(S4>7.5%, 1.5, 1.35) | ... BJ49: =IF(BJ4>7.5%, 1.5, 1.35)
A50: Saldo Insoluto | F50: 30000000 | H50: 43000000 | I50: 46000000 | J50: 52000000 | K50: 52000000
...

Sheet Efs Real
A1: Estado de resultados | B1: 44713 | C1: 44805 | D1: 44896 | E1: 44986 | F1: 45078 | G1: 45170 | H1: 45261 | I1: 45352 | J1: 45444 | K1: 45536 | L1: 45627 | M1: 45658 | N1: 45689 | O1: 45717 | P1: 45748 | Q1: 45778 | R1: 45809 | S1: 45839 | T1: 45870 | U1: 45901 | V1: 45931 | W1: 45962 | X1: 45992 | Y1: 46023 | Z1: 46054 | AA1: feb-26 restado | AD1: ER - Analisis vertical (% Comisiones cobradas) | BG1: ER - Analisis horizontal (% vs periodo anterior)
A2: Comisiones cobradas | B2: 3031000 | C2: 5147000 | D2: 7230000 | E2: 2199000 | F2: 2974000 | G2: 4870000 | H2: 7076000 | I2: 2519000 | J2: 5696000 | K2: 8874000 | L2: 12252000 | M2: 998000 | N2: =1957000-M2 | O2: =3385000-SUM(M2:N2) | P2: 1908286 | Q2: 1343719.5 | R2: =8202000-SUM($M2:Q2) | S2: 1214533.8 | T2: 1552749 | U2: =12705000-SUM($M2:T2) | V2: 2341515.2 | W2: 1066373.4 | X2: 1580714.3 | Y2: 1053000 | Z2: 2144000 | AA2: =Z2-Y2 | AD2: Comisiones cobradas | AE2: =IFERROR(B2/B$2,0) | AF2: =IFERROR(C2/C$2,0) | AG2: =IFERROR(D2/D$2,0) | AH2: =IFERROR(E2/E$2,0) | AI2: =IFERROR(F2/F$2,0) | AJ2: =IFERROR(G2/G$2,0) | AK2: =IFERROR(H2/H$2,0) | AL2: =IFERROR(I2/I$2,0) | ... BE2: =IFERROR(AB2/AB$2,0) | BG2: Comisiones cobradas | BI2: =IFERROR(C2/B2-1,0) | BJ2: =IFERROR(D2/C2-1,0) | BK2: =IFERROR(E2/D2-1,0) | BL2: =IFERROR(F2/E2-1,0) | BM2: =IFERROR(G2/F2-1,0) | BN2: =IFERROR(H2/G2-1,0) | BO2: =IFERROR(I2/H2-1,0) | BP2: =IFERROR(J2/I2-1,0) | ... CH2: =IFERROR(AB2/AA2-1,0)
A3: Comisiones pagadas | B3: -112000 | C3: -247000 | D3: -322000 | E3: -111000 | F3: -194000 | G3: -346000 | H3: -515000 | I3: -612000 | J3: -1574000 | K3: -2635000 | L3: -3675000 | M3: -415000 | N3: =-725000-M3 | O3: =-1056000-SUM(M3:N3) | P3: -195731 | Q3: -254716.28 | R3: =-1627000-SUM(M3:Q3) | S3: -245747.17 | T3: -109983.18 | U3: =-(SUM($M3:T3)+2407000) | V3: -239566.18 | W3: -96599.85 | X3: -181499.01 | Y3: -208000 | Z3: -388000 | AA3: =Z3-Y3 | AD3: Comisiones pagadas | AE3: =IFERROR(B3/B$2,0) | AF3: =IFERROR(C3/C$2,0) | AG3: =IFERROR(D3/D$2,0) | AH3: =IFERROR(E3/E$2,0) | AI3: =IFERROR(F3/F$2,0) | AJ3: =IFERROR(G3/G$2,0) | AK3: =IFERROR(H3/H$2,0) | AL3: =IFERROR(I3/I$2,0) | ... BE3: =IFERROR(AB3/AB$2,0) | BG3: Comisiones pagadas | BI3: =IFERROR(C3/B3-1,0) | BJ3: =IFERROR(D3/C3-1,0) | BK3: =IFERROR(E3/D3-1,0) | BL3: =IFERROR(F3/E3-1,0) | BM3: =IFERROR(G3/F3-1,0) | BN3: =IFERROR(H3/G3-1,0) | BO3: =IFERROR(I3/H3-1,0) | BP3: =IFERROR(J3/I3-1,0) | ... CH3: =IFERROR(AB3/AA3-1,0)
A4: Pagadas vs Cobradas | B4: =-B3/B2 | C4: =-C3/C2 | D4: =-D3/D2 | E4: =-E3/E2 | F4: =-F3/F2 | G4: =-G3/G2 | H4: =-H3/H2 | I4: =-I3/I2 | ... Z4: =-Z3/Z2 | AA4: =Z4-Y4 | AD4: Pagadas vs Cobradas | AE4: =IFERROR(B4/B$2,0) | AF4: =IFERROR(C4/C$2,0) | AG4: =IFERROR(D4/D$2,0) | AH4: =IFERROR(E4/E$2,0) | AI4: =IFERROR(F4/F$2,0) | AJ4: =IFERROR(G4/G$2,0) | AK4: =IFERROR(H4/H$2,0) | AL4: =IFERROR(I4/I$2,0) | ... BE4: =IFERROR(AB4/AB$2,0) | BG4: Pagadas vs Cobradas | BI4: =IFERROR(C4/B4-1,0) | BJ4: =IFERROR(D4/C4-1,0) | BK4: =IFERROR(E4/D4-1,0) | BL4: =IFERROR(F4/E4-1,0) | BM4: =IFERROR(G4/F4-1,0) | BN4: =IFERROR(H4/G4-1,0) | BO4: =IFERROR(I4/H4-1,0) | BP4: =IFERROR(J4/I4-1,0) | ... CH4: =IFERROR(AB4/AA4-1,0)
A5: Resultado por Servicios | B5: 2919000 | C5: 4900000 | D5: 6908000 | E5: 2088000 | F5: 2780000 | G5: 4524000 | H5: 6561000 | I5: 1907000 | J5: 4122000 | K5: =SUM(K2:K3) | L5: =SUM(L2:L3) | M5: =SUM(M2:M3) | N5: =SUM(N2:N3) | O5: =SUM(O2:O3) | P5: =SUM(P2:P3) | Q5: =SUM(Q2:Q3) | R5: =SUM(R2:R3) | ... Z5: =SUM(Z2:Z3) | AA5: =Z5-Y5 | AD5: Resultado por Servicios | AE5: =IFERROR(B5/B$2,0) | AF5: =IFERROR(C5/C$2,0) | AG5: =IFERROR(D5/D$2,0) | AH5: =IFERROR(E5/E$2,0) | AI5: =IFERROR(F5/F$2,0) | AJ5: =IFERROR(G5/G$2,0) | AK5: =IFERROR(H5/H$2,0) | AL5: =IFERROR(I5/I$2,0) | ... BE5: =IFERROR(AB5/AB$2,0) | BG5: Resultado por Servicios | BI5: =IFERROR(C5/B5-1,0) | BJ5: =IFERROR(D5/C5-1,0) | BK5: =IFERROR(E5/D5-1,0) | BL5: =IFERROR(F5/E5-1,0) | BM5: =IFERROR(G5/F5-1,0) | BN5: =IFERROR(H5/G5-1,0) | BO5: =IFERROR(I5/H5-1,0) | BP5: =IFERROR(J5/I5-1,0) | ... CH5: =IFERROR(AB5/AA5-1,0)
A6: Ingresos por intereses | B6: 357000 | C6: 656000 | D6: 880000 | E6: 262000 | F6: 699000 | G6: 874000 | H6: 1256000 | I6: 386000 | J6: 761000 | K6: 1093000 | L6: 1569000 | M6: 286000 | N6: =731000-M6 | O6: =1121000-SUM(M6:N6) | P6: 566720 | Q6: 733525.58 | R6: =3124000-SUM(M6:Q6) | S6: 806638.8 | T6: 855943.36 | U6: =5540000-SUM($M6:T6) | V6: 1288378.6 | W6: 865868.25 | X6: 1031707.3 | Y6: 713000 | Z6: 1437000 | AA6: =Z6-Y6 | AD6: Ingresos por intereses | AE6: =IFERROR(B6/B$2,0) | AF6: =IFERROR(C6/C$2,0) | AG6: =IFERROR(D6/D$2,0) | AH6: =IFERROR(E6/E$2,0) | AI6: =IFERROR(F6/F$2,0) | AJ6: =IFERROR(G6/G$2,0) | AK6: =IFERROR(H6/H$2,0) | AL6: =IFERROR(I6/I$2,0) | ... BE6: =IFERROR(AB6/AB$2,0) | BG6: Ingresos por intereses | BI6: =IFERROR(C6/B6-1,0) | BJ6: =IFERROR(D6/C6-1,0) | BK6: =IFERROR(E6/D6-1,0) | BL6: =IFERROR(F6/E6-1,0) | BM6: =IFERROR(G6/F6-1,0) | BN6: =IFERROR(H6/G6-1,0) | BO6: =IFERROR(I6/H6-1,0) | BP6: =IFERROR(J6/I6-1,0) | ... CH6: =IFERROR(AB6/AA6-1,0)
A7: Resultado por valuación a valor razonable | B7: 1000 | C7: 231000 | D7: 263000 | E7: 19000 | F7: 538000 | G7: 1252000 | H7: 1282000 | I7: 1000 | J7: 1000 | K7: 1000 | L7: 1000 | M7: 0 | N7: =0-M7 | O7: 0 | P7: 0 | Q7: -724598.78 | R7: =-1706000-SUM(M7:Q7) | S7: 0 | T7: -990373.36 | U7: =SUM($M7:T7)+2696000 | V7: 0 | W7: -476229.42 | X7: 0 | Y7: 0 | Z7: 0 | AA7: =Z7-Y7 | AD7: Resultado por valuación a valor razonable | AE7: =IFERROR(B7/B$2,0) | AF7: =IFERROR(C7/C$2,0) | AG7: =IFERROR(D7/D$2,0) | AH7: =IFERROR(E7/E$2,0) | AI7: =IFERROR(F7/F$2,0) | AJ7: =IFERROR(G7/G$2,0) | AK7: =IFERROR(H7/H$2,0) | AL7: =IFERROR(I7/I$2,0) | ... BE7: =IFERROR(AB7/AB$2,0) | BG7: Resultado por valuación a valor razonable | BI7: =IFERROR(C7/B7-1,0) | BJ7: =IFERROR(D7/C7-1,0) | BK7: =IFERROR(E7/D7-1,0) | BL7: =IFERROR(F7/E7-1,0) | BM7: =IFERROR(G7/F7-1,0) | BN7: =IFERROR(H7/G7-1,0) | BO7: =IFERROR(I7/H7-1,0) | BP7: =IFERROR(J7/I7-1,0) | ... CH7: =IFERROR(AB7/AA7-1,0)
A8: Gastos por Intereses | B8: -144000 | C8: -245000 | D8: -245000 | E8: 0 | F8: 0 | G8: 0 | H8: 0 | I8: 0 | J8: 0 | K8: 0 | L8: -238000 | M8: 0 | N8: =-188000-M8 | O8: =-305000-SUM(M8:N8) | P8: 0 | Q8: -898013.89 | R8: =-1867000-SUM(M8:Q8) | S8: -844486.11 | T8: -917944.44 | U8: =-(SUM($M8:T8)+4517000) | V8: -917944.45 | W8: -858722.21 | X8: -962823.51 | Y8: -943000 | Z8: -1779000 | AA8: =Z8-Y8 | AD8: Gastos por Intereses | AE8: =IFERROR(B8/B$2,0) | AF8: =IFERROR(C8/C$2,0) | AG8: =IFERROR(D8/D$2,0) | AH8: =IFERROR(E8/E$2,0) | AI8: =IFERROR(F8/F$2,0) | AJ8: =IFERROR(G8/G$2,0) | AK8: =IFERROR(H8/H$2,0) | AL8: =IFERROR(I8/I$2,0) | ... BE8: =IFERROR(AB8/AB$2,0) | BG8: Gastos por Intereses | BI8: =IFERROR(C8/B8-1,0) | BJ8: =IFERROR(D8/C8-1,0) | BK8: =IFERROR(E8/D8-1,0) | BL8: =IFERROR(F8/E8-1,0) | BM8: =IFERROR(G8/F8-1,0) | BN8: =IFERROR(H8/G8-1,0) | BO8: =IFERROR(I8/H8-1,0) | BP8: =IFERROR(J8/I8-1,0) | ... CH8: =IFERROR(AB8/AA8-1,0)
A9: Margen Financiero por Intermediación | B9: 3133000 | C9: 5542000 | D9: 7806000 | E9: 2369000 | F9: 4017000 | G9: 6650000 | H9: 9099000 | I9: 2294000 | J9: 4884000 | K9: 7333000 | L9: =SUM(L6:L8)+L5 | M9: =SUM(M6:M8)+M5 | N9: =SUM(N6:N8)+N5 | O9: =SUM(O6:O8)+O5 | P9: =SUM(P6:P8)+P5 | Q9: =SUM(Q6:Q8)+Q5 | R9: =R5+SUM(R6:R8) | S9: =S5+SUM(S6:S8) | T9: =T5+SUM(T6:T8) | U9: =U5+SUM(U6:U8) | V9: =V5+SUM(V6:V8) | W9: =W5+SUM(W6:W8) | X9: =X5+SUM(X6:X8) | Y9: =Y5+SUM(Y6:Y8) | Z9: =Z5+Z6+Z8 | AA9: =Z9-Y9 | AD9: Margen Financiero por Intermediación | AE9: =IFERROR(B9/B$2,0) | AF9: =IFERROR(C9/C$2,0) | AG9: =IFERROR(D9/D$2,0) | AH9: =IFERROR(E9/E$2,0) | AI9: =IFERROR(F9/F$2,0) | AJ9: =IFERROR(G9/G$2,0) | AK9: =IFERROR(H9/H$2,0) | AL9: =IFERROR(I9/I$2,0) | ... BE9: =IFERROR(AB9/AB$2,0) | BG9: Margen Financiero por Intermediación | BI9: =IFERROR(C9/B9-1,0) | BJ9: =IFERROR(D9/C9-1,0) | BK9: =IFERROR(E9/D9-1,0) | BL9: =IFERROR(F9/E9-1,0) | BM9: =IFERROR(G9/F9-1,0) | BN9: =IFERROR(H9/G9-1,0) | BO9: =IFERROR(I9/H9-1,0) | BP9: =IFERROR(J9/I9-1,0) | ... CH9: =IFERROR(AB9/AA9-1,0)
A10: Otros ingresos (egresos) de la operación | B10: 1886000 | C10: 1882000 | D10: 1597000 | E10: -401000 | F10: -512000 | G10: -565000 | H10: -602000 | I10: 67000 | J10: 65000 | K10: 171000 | L10: 144000 | M10: -4000 | N10: =-47000-M10 | O10: =-91000-SUM(M10:N10) | P10: -27793 | Q10: -155119.55 | R10: =-444000-SUM(M10:Q10) | S10: -159333.15 | T10: -258050.5 | U10: =-(SUM($M10:T10)+1098000) | V10: -462793.95 | W10: -466796.14 | X10: -156531.81 | Y10: -38000 | Z10: -84000 | AA10: =Z10-Y10 | AD10: Otros ingresos (egresos) de la operación | AE10: =IFERROR(B10/B$2,0) | AF10: =IFERROR(C10/C$2,0) | AG10: =IFERROR(D10/D$2,0) | AH10: =IFERROR(E10/E$2,0) | AI10: =IFERROR(F10/F$2,0) | AJ10: =IFERROR(G10/G$2,0) | AK10: =IFERROR(H10/H$2,0) | AL10: =IFERROR(I10/I$2,0) | ... BE10: =IFERROR(AB10/AB$2,0) | BG10: Otros ingresos (egresos) de la operación | BI10: =IFERROR(C10/B10-1,0) | BJ10: =IFERROR(D10/C10-1,0) | BK10: =IFERROR(E10/D10-1,0) | BL10: =IFERROR(F10/E10-1,0) | BM10: =IFERROR(G10/F10-1,0) | BN10: =IFERROR(H10/G10-1,0) | BO10: =IFERROR(I10/H10-1,0) | BP10: =IFERROR(J10/I10-1,0) | ... CH10: =IFERROR(AB10/AA10-1,0)
A11: Gastos de Administración y Promoción | B11: -4616000 | C11: -7689000 | D11: -13731000 | E11: -3446000 | F11: -7176000 | G11: -11329000 | H11: -15660000 | I11: -4272000 | J11: -8109000 | K11: -12211000 | L11: -16138000 | M11: -1622000 | N11: =-2677000-M11 | O11: =-4358000-SUM(M11:N11) | P11: -1590408 | Q11: -1955019.4 | R11: =-9500000-SUM(M11:Q11) | S11: -1598596.9 | T11: -1622859 | U11: =-(SUM($M11:T11)+13964000) | V11: -1908771.3 | W11: -1615578.5 | X11: -1791374.2 | Y11: -2031000 | Z11: -3703000 | AA11: =Z11-Y11 | AD11: Gastos de Administración y Promoción | AE11: =IFERROR(B11/B$2,0) | AF11: =IFERROR(C11/C$2,0) | AG11: =IFERROR(D11/D$2,0) | AH11: =IFERROR(E11/E$2,0) | AI11: =IFERROR(F11/F$2,0) | AJ11: =IFERROR(G11/G$2,0) | AK11: =IFERROR(H11/H$2,0) | AL11: =IFERROR(I11/I$2,0) | ... BE11: =IFERROR(AB11/AB$2,0) | BG11: Gastos de Administración y Promoción | BI11: =IFERROR(C11/B11-1,0) | BJ11: =IFERROR(D11/C11-1,0) | BK11: =IFERROR(E11/D11-1,0) | BL11: =IFERROR(F11/E11-1,0) | BM11: =IFERROR(G11/F11-1,0) | BN11: =IFERROR(H11/G11-1,0) | BO11: =IFERROR(I11/H11-1,0) | BP11: =IFERROR(J11/I11-1,0) | ... CH11: =IFERROR(AB11/AA11-1,0)
A12: Impuestos a la utilidad y diferido | B12: 434000 | C12: 378000 | D12: 449000 | E12: 0 | F12: -154000 | G12: -174000 | H12: -332000 | I12: 0 | J12: 0 | K12: 0 | L12: 0 | M12: 0 | N12: =0-M12 | O12: 0 | P12: 0 | Q12: 0 | R12: =0-SUM(M12:Q12) | S12: =0-SUM(N12:R12) | T12: =0-SUM(O12:S12) | U12: =SUM($M12:T12)+0 | V12: 0 | Y12: 0 | Z12: 0 | AA12: =Z12-Y12 | AD12: Impuestos a la utilidad y diferido | AE12: =IFERROR(B12/B$2,0) | AF12: =IFERROR(C12/C$2,0) | AG12: =IFERROR(D12/D$2,0) | AH12: =IFERROR(E12/E$2,0) | AI12: =IFERROR(F12/F$2,0) | AJ12: =IFERROR(G12/G$2,0) | AK12: =IFERROR(H12/H$2,0) | AL12: =IFERROR(I12/I$2,0) | ... BE12: =IFERROR(AB12/AB$2,0) | BG12: Impuestos a la utilidad y diferido | BI12: =IFERROR(C12/B12-1,0) | BJ12: =IFERROR(D12/C12-1,0) | BK12: =IFERROR(E12/D12-1,0) | BL12: =IFERROR(F12/E12-1,0) | BM12: =IFERROR(G12/F12-1,0) | BN12: =IFERROR(H12/G12-1,0) | BO12: =IFERROR(I12/H12-1,0) | BP12: =IFERROR(J12/I12-1,0) | ... CH12: =IFERROR(AB12/AA12-1,0)
A13: Resultado Neto | B13: 837000 | C13: 113000 | D13: -3879000 | E13: -1478000 | F13: -3825000 | G13: -5418000 | H13: -7495000 | I13: -1911000 | J13: -3160000 | K13: -4707000 | L13: =SUM(L10:L12)+L9 | M13: =SUM(M10:M12)+M9 | N13: =SUM(N10:N12)+N9 | O13: =SUM(O10:O12)+O9 | P13: =SUM(P10:P12)+P9 | Q13: =SUM(Q10:Q12)+Q9 | R13: =SUM(R10:R12)+R9 | S13: =SUM(S10:S12)+S9 | ... Y13: =SUM(Y10:Y12)+Y9 | Z13: =Z9+Z10+Z11 | AA13: =Z13-Y13 | AD13: Resultado Neto | AE13: =IFERROR(B13/B$2,0) | AF13: =IFERROR(C13/C$2,0) | AG13: =IFERROR(D13/D$2,0) | AH13: =IFERROR(E13/E$2,0) | AI13: =IFERROR(F13/F$2,0) | AJ13: =IFERROR(G13/G$2,0) | AK13: =IFERROR(H13/H$2,0) | AL13: =IFERROR(I13/I$2,0) | ... BE13: =IFERROR(AB13/AB$2,0) | BG13: Resultado Neto | BI13: =IFERROR(C13/B13-1,0) | BJ13: =IFERROR(D13/C13-1,0) | BK13: =IFERROR(E13/D13-1,0) | BL13: =IFERROR(F13/E13-1,0) | BM13: =IFERROR(G13/F13-1,0) | BN13: =IFERROR(H13/G13-1,0) | BO13: =IFERROR(I13/H13-1,0) | BP13: =IFERROR(J13/I13-1,0) | ... CH13: =IFERROR(AB13/AA13-1,0)
B14: 6 | C14: 9 | D14: 12 | E14: 3 | F14: 6 | G14: 9 | H14: 12 | I14: 3 | J14: 6 | K14: 9 | L14: 12 | M14: 1 | N14: 2 | V14: | | W14: | | X14: | | Y14: |
A15: Cuentas Bajo Administración | B15: 44713 | C15: 44805 | D15: 44896 | E15: 44986 | F15: 45078 | G15: 45170 | H15: 45261 | I15: 45352 | J15: 45444 | K15: 45536 | L15: 45627 | M15: 45658 | N15: 45689 | O15: 45717 | P15: 45748 | Q15: 45778 | R15: 45809 | S15: 45839 | T15: 45870 | U15: 45901 | V15: 45931 | W15: 45931 | X15: 45992 | Y15: 46023 | Z15: 46054
A16: Deuda cuentas corrientes | B16: 2339000 | C16: 3307000 | D16: 5406000 | E16: 4330000 | F16: 4512000 | G16: 4995000 | H16: 6718000 | I16: 5575000 | J16: 5215000 | K16: 6889000 | L16: 11052000 | M16: 10315000 | N16: 10349000 | O16: 10201000 | P16: 6418014 | R16: 3424000 | U16: 4130000 | Y16: 5222000 | Z16: 7042000
A17: Depósitos de inversionistas | B17: 4458000 | C17: 5356000 | D17: 4906000 | E17: 7587000 | F17: 7267000 | G17: 6142000 | H17: 6825000 | I17: 8451000 | J17: 9034000 | K17: 8643000 | L17: 7734000 | M17: 7538000 | N17: 7236000 | O17: 7543000 | P17: 10336837 | R17: 11544000 | U17: 7770000 | Y17: 7943000 | Z17: 10938000
A18: Otras cuentas corrientes | B18: 6524000 | C18: 8079000 | D18: 10063000 | E18: 11779000 | F18: 11608000 | G18: 10980000 | H18: 13791000 | I18: 13851000 | J18: 13566000 | K18: 15240000 | L18: 17276000 | M18: 13842000 | N18: 17655000 | O18: 18747000 | P18: 17709968 | R18: 0 | U18: 12210000 | Y18: 13241000 | Z18: 17906000
A19: Instrumentos financieros de clientes en administración | B19: 97373000 | C19: 100058000 | D19: 111072000 | E19: 116535000 | F19: 119344000 | G19: 130759000 | H19: 136571000 | I19: 152097000 | J19: 152920000 | K19: 160492000 | L19: 173957000 | M19: 175565000 | N19: 173917000 | O19: 184923000 | P19: 194537486 | R19: 202657000 | U19: 204013000 | Y19: 196293000 | Z19: 196245000
A20: Comisiones vs. Cartera | B20: =(B2/B14*12)/B19 | C20: =(C2/C14*12)/C19 | D20: =(D2/D14*12)/D19 | E20: =(E2/E14*12)/E19 | F20: =(F2/F14*12)/F19 | G20: =(G2/G14*12)/G19 | H20: =(H2/H14*12)/H19 | I20: =(I2/I14*12)/I19 | ... L20: =(L2/L14*12)/L19 | M20: =(M2*12)/M19 | N20: =(N2*12)/N19 | O20: =(O2*12)/O19 | P20: =(P2*12)/P19 | Q20: =(Q2*12)/Q19 | R20: =(R2*12)/R19 | U20: =(U2*12)/U19 | V20: =(V2*12)/V19 | W20: =(W2*12)/W19 | X20: =(X2*12)/X19 | Y20: =(Y2*12)/Y19 | Z20: =(Z2*12)/Z19
A21: Colaterales recibidos en garanía por cuenta de solicitantes | B21: 117285000 | C21: 125400000 | D21: 134270000 | E21: 151502000 | F21: 166160000 | G21: 186115000 | H21: 203482000 | I21: 198647000 | J21: 208366000 | K21: 216152000 | L21: 231653000 | M21: 233750000 | N21: 242718000 | O21: 247111000 | P21: 253062289 | R21: 271081000 | U21: 270589000 | Y21: 252127000 | Z21: 252751000
A22: Total Operaciones de Administración | B22: 227979000 | C22: 242200000 | D22: 265717000 | E22: 291733000 | F22: 308891000 | G22: 338991000 | H22: 367387000 | I22: 378621000 | J22: 389101000 | K22: 407416000 | L22: =L21+L19+L18+L17+L16 | M22: =M21+M19+M18+M17+M16 | N22: =N21+N19+N18+N17+N16 | O22: =O21+O19+O18+O17+O16 | P22: =P21+P19+P18+P17+P16 | Q22: =Q21+Q19+Q18+Q17+Q16 | R22: =R21+R19+R18+R17+R16 | U22: =U21+U19+U18+U17+U16 | V22: =V21+V19+V18+V17+V16 | W22: =W21+W19+W18+W17+W16 | X22: =X21+X19+X18+X17+X16 | Y22: =Y21+Y19+Y18+Y17+Y16 | Z22: =Z21+Z19+Z18+Z17+Z16
M23: 1 | N23: 2
A24: Balance General | B24: 44713 | C24: 44805 | D24: 44896 | E24: 44986 | F24: 45078 | G24: 45170 | H24: 45261 | I24: 45352 | J24: 45444 | K24: 45536 | L24: 45627 | M24: 45658 | N24: 45689 | O24: 45717 | P24: 45748 | Q24: 45778 | R24: 45809 | S24: 45839 | T24: 45870 | U24: 45901 | V24: 45931 | W24: 45931 | X24: 45992 | Y24: 46023 | Z24: 46054 | AD24: BG - Analisis vertical (% Total Activo) | BG24: BG - Analisis horizontal (% vs periodo anterior)
A25: Efectivo y equivalentes de efectivo | B25: 544000 | C25: 6371000 | D25: 1962000 | E25: 3241000 | F25: 2397000 | G25: 3151000 | H25: 945000 | I25: 113000 | J25: 634000 | K25: 458000 | L25: 334000 | M25: 678000 | N25: 65000 | O25: 443000 | P25: 279981 | Q25: 1501430.3 | R25: 253000 | S25: 661157.8 | T25: 62726.5 | U25: 121000 | V25: 401123.31 | W25: 687768.41 | X25: 290091.8 | Y25: 160000 | Z25: 813000 | AD25: Efectivo y equivalentes de efectivo | AE25: =IFERROR(B25/B$33,0) | AF25: =IFERROR(C25/C$33,0) | AG25: =IFERROR(D25/D$33,0) | AH25: =IFERROR(E25/E$33,0) | AI25: =IFERROR(F25/F$33,0) | AJ25: =IFERROR(G25/G$33,0) | AK25: =IFERROR(H25/H$33,0) | AL25: =IFERROR(I25/I$33,0) | ... BE25: =IFERROR(AB25/AB$33,0) | BG25: Efectivo y equivalentes de efectivo | BI25: =IFERROR(C25/B25-1,0) | BJ25: =IFERROR(D25/C25-1,0) | BK25: =IFERROR(E25/D25-1,0) | BL25: =IFERROR(F25/E25-1,0) | BM25: =IFERROR(G25/F25-1,0) | BN25: =IFERROR(H25/G25-1,0) | BO25: =IFERROR(I25/H25-1,0) | BP25: =IFERROR(J25/I25-1,0) | ... CH25: =IFERROR(AB25/AA25-1,0)
A26: Inversiones en instrumentos financieros (cartera RG) | B26: 6209000 | C26: 6678000 | D26: 6905000 | E26: 6430000 | F26: 6187000 | G26: 1298000 | H26: 1996000 | I26: 1476000 | J26: 1516000 | K26: 6208000 | L26: 25517000 | M26: 24388000 | N26: 24356000 | O26: 38503000 | P26: 50875285 | Q26: 50875230 | R26: 61878000 | S26: 72564877 | T26: 72334955 | U26: 69199000 | V26: 77800817 | W26: 72500790 | X26: 64999893 | Y26: 63365000 | Z26: 61408000 | AD26: Inversiones en instrumentos financieros (cartera RG) | AE26: =IFERROR(B26/B$33,0) | AF26: =IFERROR(C26/C$33,0) | AG26: =IFERROR(D26/D$33,0) | AH26: =IFERROR(E26/E$33,0) | AI26: =IFERROR(F26/F$33,0) | AJ26: =IFERROR(G26/G$33,0) | AK26: =IFERROR(H26/H$33,0) | AL26: =IFERROR(I26/I$33,0) | ... BE26: =IFERROR(AB26/AB$33,0) | BG26: Inversiones en instrumentos financieros (cartera RG) | BI26: =IFERROR(C26/B26-1,0) | BJ26: =IFERROR(D26/C26-1,0) | BK26: =IFERROR(E26/D26-1,0) | BL26: =IFERROR(F26/E26-1,0) | BM26: =IFERROR(G26/F26-1,0) | BN26: =IFERROR(H26/G26-1,0) | BO26: =IFERROR(I26/H26-1,0) | BP26: =IFERROR(J26/I26-1,0) | ... CH26: =IFERROR(AB26/AA26-1,0)
A27: Estimación de pérdidas crediticias | B27: -1683000 | C27: -1495000 | D27: -1548000 | E27: -1550000 | F27: -1221000 | G27: -403000 | H27: -403000 | I27: -403000 | J27: -403000 | K27: -403000 | L27: -403000 | M27: -403000 | N27: -403000 | O27: -2503000 | P27: -2503265 | Q27: -3227863.7 | R27: -4209000 | S27: -4209174.6 | T27: -5199548 | U27: -5200000 | V27: -5199548 | W27: -5675777.4 | X27: -5675777.4 | Y27: -5676000 | Z27: -5676000 | AD27: Estimación de pérdidas crediticias | AE27: =IFERROR(B27/B$33,0) | AF27: =IFERROR(C27/C$33,0) | AG27: =IFERROR(D27/D$33,0) | AH27: =IFERROR(E27/E$33,0) | AI27: =IFERROR(F27/F$33,0) | AJ27: =IFERROR(G27/G$33,0) | AK27: =IFERROR(H27/H$33,0) | AL27: =IFERROR(I27/I$33,0) | ... BE27: =IFERROR(AB27/AB$33,0) | BG27: Estimación de pérdidas crediticias | BI27: =IFERROR(C27/B27-1,0) | BJ27: =IFERROR(D27/C27-1,0) | BK27: =IFERROR(E27/D27-1,0) | BL27: =IFERROR(F27/E27-1,0) | BM27: =IFERROR(G27/F27-1,0) | BN27: =IFERROR(H27/G27-1,0) | BO27: =IFERROR(I27/H27-1,0) | BP27: =IFERROR(J27/I27-1,0) | ... CH27: =IFERROR(AB27/AA27-1,0)
A28: Cuentas por cobrar, neto | B28: 325000 | C28: 1231000 | D28: 6980000 | E28: 7253000 | F28: 7160000 | G28: 11824000 | H28: 11779000 | I28: 11677000 | J28: 11821000 | K28: 11405000 | L28: 11266000 | M28: 11398000 | N28: 13552000 | O28: 12011000 | P28: 12321419 | Q28: 12473029 | R28: 11183000 | S28: 11623339 | T28: 12428384 | U28: 13152000 | V28: 13035761 | W28: 11717400 | X28: 12311004 | Y28: 12186000 | Z28: 12264000 | AD28: Cuentas por cobrar, neto | AE28: =IFERROR(B28/B$33,0) | AF28: =IFERROR(C28/C$33,0) | AG28: =IFERROR(D28/D$33,0) | AH28: =IFERROR(E28/E$33,0) | AI28: =IFERROR(F28/F$33,0) | AJ28: =IFERROR(G28/G$33,0) | AK28: =IFERROR(H28/H$33,0) | AL28: =IFERROR(I28/I$33,0) | ... BE28: =IFERROR(AB28/AB$33,0) | BG28: Cuentas por cobrar, neto | BI28: =IFERROR(C28/B28-1,0) | BJ28: =IFERROR(D28/C28-1,0) | BK28: =IFERROR(E28/D28-1,0) | BL28: =IFERROR(F28/E28-1,0) | BM28: =IFERROR(G28/F28-1,0) | BN28: =IFERROR(H28/G28-1,0) | BO28: =IFERROR(I28/H28-1,0) | BP28: =IFERROR(J28/I28-1,0) | ... CH28: =IFERROR(AB28/AA28-1,0)
A29: Pagos anticipados y otros activos, neto | B29: 1630000 | C29: 2000000 | D29: 2472000 | E29: 1696000 | F29: 1675000 | G29: 1529000 | H29: 1549000 | I29: 1511000 | J29: 1460000 | K29: 1419000 | L29: 1382000 | M29: 1617000 | N29: 1450000 | O29: 2747000 | P29: 4619536 | Q29: =2271537.47+3494711.12+1037057.22 | R29: 7792000 | S29: 4781463.7 | T29: 5390587.6 | U29: 6322000 | V29: 7862889 | W29: 7908494.4 | X29: 10047810 | Y29: 11203000 | Z29: 12406000 | AD29: Pagos anticipados y otros activos, neto | AE29: =IFERROR(B29/B$33,0) | AF29: =IFERROR(C29/C$33,0) | AG29: =IFERROR(D29/D$33,0) | AH29: =IFERROR(E29/E$33,0) | AI29: =IFERROR(F29/F$33,0) | AJ29: =IFERROR(G29/G$33,0) | AK29: =IFERROR(H29/H$33,0) | AL29: =IFERROR(I29/I$33,0) | ... BE29: =IFERROR(AB29/AB$33,0) | BG29: Pagos anticipados y otros activos, neto | BI29: =IFERROR(C29/B29-1,0) | BJ29: =IFERROR(D29/C29-1,0) | BK29: =IFERROR(E29/D29-1,0) | BL29: =IFERROR(F29/E29-1,0) | BM29: =IFERROR(G29/F29-1,0) | BN29: =IFERROR(H29/G29-1,0) | BO29: =IFERROR(I29/H29-1,0) | BP29: =IFERROR(J29/I29-1,0) | ... CH29: =IFERROR(AB29/AA29-1,0)
A30: Propiedades, mobiliario y equipo, neto | B30: 132000 | C30: 114000 | D30: 96000 | E30: 109000 | F30: 180000 | G30: 174000 | H30: 207000 | I30: 208000 | J30: 210000 | K30: 208000 | L30: 238000 | M30: 235000 | N30: 232000 | O30: 243000 | P30: 242599 | Q30: 642052.93 | R30: 300000 | S30: 656383.1 | T30: 656383.1 | U30: 301000 | V30: 684494.31 | W30: 684494.31 | X30: 684494.31 | Y30: 452000 | Z30: 394000 | AD30: Propiedades, mobiliario y equipo, neto | AE30: =IFERROR(B30/B$33,0) | AF30: =IFERROR(C30/C$33,0) | AG30: =IFERROR(D30/D$33,0) | AH30: =IFERROR(E30/E$33,0) | AI30: =IFERROR(F30/F$33,0) | AJ30: =IFERROR(G30/G$33,0) | AK30: =IFERROR(H30/H$33,0) | AL30: =IFERROR(I30/I$33,0) | ... BE30: =IFERROR(AB30/AB$33,0) | BG30: Propiedades, mobiliario y equipo, neto | BI30: =IFERROR(C30/B30-1,0) | BJ30: =IFERROR(D30/C30-1,0) | BK30: =IFERROR(E30/D30-1,0) | BL30: =IFERROR(F30/E30-1,0) | BM30: =IFERROR(G30/F30-1,0) | BN30: =IFERROR(H30/G30-1,0) | BO30: =IFERROR(I30/H30-1,0) | BP30: =IFERROR(J30/I30-1,0) | ... CH30: =IFERROR(AB30/AA30-1,0)
A31: Depreciación acumulada | Q31: -354157.06 | R31: 0 | S31: -354947.44 | T31: -355342.63 | U31: 0 | V31: -356133.01 | W31: -356528.2 | X31: -356923.39 | Y31: 0 | AD31: Depreciación acumulada | AE31: =IFERROR(B31/B$33,0) | AF31: =IFERROR(C31/C$33,0) | AG31: =IFERROR(D31/D$33,0) | AH31: =IFERROR(E31/E$33,0) | AI31: =IFERROR(F31/F$33,0) | AJ31: =IFERROR(G31/G$33,0) | AK31: =IFERROR(H31/H$33,0) | AL31: =IFERROR(I31/I$33,0) | ... BE31: =IFERROR(AB31/AB$33,0) | BG31: Depreciación acumulada | BI31: =IFERROR(C31/B31-1,0) | BJ31: =IFERROR(D31/C31-1,0) | BK31: =IFERROR(E31/D31-1,0) | BL31: =IFERROR(F31/E31-1,0) | BM31: =IFERROR(G31/F31-1,0) | BN31: =IFERROR(H31/G31-1,0) | BO31: =IFERROR(I31/H31-1,0) | BP31: =IFERROR(J31/I31-1,0) | ... CH31: =IFERROR(AB31/AA31-1,0)
A32: Activo por impuestos a la utilidad diferidos, neto | B32: 505000 | C32: 449000 | D32: 520000 | E32: 521000 | F32: 366000 | G32: 346000 | H32: 268000 | I32: 346000 | J32: 346000 | K32: 346000 | L32: 346000 | M32: 346000 | N32: 346000 | O32: 1082000 | P32: 1082189 | Q32: 1082189.3 | R32: 1082000 | S32: 1082189.3 | T32: 1082189.3 | U32: 1082000 | V32: 1082189.3 | W32: 1082189.3 | X32: 1082189.3 | Y32: 1361000 | Z32: 1669000 | AD32: Activo por impuestos a la utilidad diferidos, neto | AE32: =IFERROR(B32/B$33,0) | AF32: =IFERROR(C32/C$33,0) | AG32: =IFERROR(D32/D$33,0) | AH32: =IFERROR(E32/E$33,0) | AI32: =IFERROR(F32/F$33,0) | AJ32: =IFERROR(G32/G$33,0) | AK32: =IFERROR(H32/H$33,0) | AL32: =IFERROR(I32/I$33,0) | ... BE32: =IFERROR(AB32/AB$33,0) | BG32: Activo por impuestos a la utilidad diferidos, neto | BI32: =IFERROR(C32/B32-1,0) | BJ32: =IFERROR(D32/C32-1,0) | BK32: =IFERROR(E32/D32-1,0) | BL32: =IFERROR(F32/E32-1,0) | BM32: =IFERROR(G32/F32-1,0) | BN32: =IFERROR(H32/G32-1,0) | BO32: =IFERROR(I32/H32-1,0) | BP32: =IFERROR(J32/I32-1,0) | ... CH32: =IFERROR(AB32/AA32-1,0)
A33: Total Activo | B33: =SUM(B25:B32) | C33: =SUM(C25:C32) | D33: =SUM(D25:D32) | E33: =SUM(E25:E32) | F33: =SUM(F25:F32) | G33: =SUM(G25:G32) | H33: =SUM(H25:H32) | I33: =SUM(I25:I32) | ... Z33: =SUM(Z25:Z32) | AD33: Total Activo | AE33: =IFERROR(B33/B$33,0) | AF33: =IFERROR(C33/C$33,0) | AG33: =IFERROR(D33/D$33,0) | AH33: =IFERROR(E33/E$33,0) | AI33: =IFERROR(F33/F$33,0) | AJ33: =IFERROR(G33/G$33,0) | AK33: =IFERROR(H33/H$33,0) | AL33: =IFERROR(I33/I$33,0) | ... BE33: =IFERROR(AB33/AB$33,0) | BG33: Total Activo | BI33: =IFERROR(C33/B33-1,0) | BJ33: =IFERROR(D33/C33-1,0) | BK33: =IFERROR(E33/D33-1,0) | BL33: =IFERROR(F33/E33-1,0) | BM33: =IFERROR(G33/F33-1,0) | BN33: =IFERROR(H33/G33-1,0) | BO33: =IFERROR(I33/H33-1,0) | BP33: =IFERROR(J33/I33-1,0) | ... CH33: =IFERROR(AB33/AA33-1,0)
A35: Préstamos de corto plazo | B35: 1058000 | C35: 115000 | D35: 17000 | E35: 50000 | F35: 89000 | G35: 142000 | H35: 114000 | I35: 255000 | J35: 59000 | K35: 139000 | L35: 60000 | M35: 75000 | N35: 358000 | O35: 0 | P35: 86288 | Q35: 164643.18 | R35: 81000 | S35: 119104.48 | T35: 101245.29 | U35: 374000 | V35: 178760.11 | W35: 72353.39 | X35: 66838.97 | Y35: 378000 | Z35: 94000 | AD35: Préstamos de corto plazo | AE35: =IFERROR(B35/B$33,0) | AF35: =IFERROR(C35/C$33,0) | AG35: =IFERROR(D35/D$33,0) | AH35: =IFERROR(E35/E$33,0) | AI35: =IFERROR(F35/F$33,0) | AJ35: =IFERROR(G35/G$33,0) | AK35: =IFERROR(H35/H$33,0) | AL35: =IFERROR(I35/I$33,0) | ... BE35: =IFERROR(AB35/AB$33,0) | BG35: Préstamos de corto plazo | BI35: =IFERROR(C35/B35-1,0) | BJ35: =IFERROR(D35/C35-1,0) | BK35: =IFERROR(E35/D35-1,0) | BL35: =IFERROR(F35/E35-1,0) | BM35: =IFERROR(G35/F35-1,0) | BN35: =IFERROR(H35/G35-1,0) | BO35: =IFERROR(I35/H35-1,0) | BP35: =IFERROR(J35/I35-1,0) | ... CH35: =IFERROR(AB35/AA35-1,0)
A36: Préstamos de largo plazo | B36: 1477000 | C36: 10611000 | D36: 10405000 | E36: 9400000 | F36: 8803000 | G36: 8206000 | H36: 7609000 | I36: 7459000 | J36: 6862000 | K36: 11265000 | L36: 10465000 | M36: 10334000 | N36: 10465000 | O36: 24549000 | P36: 34468353 | Q36: 38468353 | R36: 47070000 | S36: 55574615 | T36: =55574614.97 | U36: 55327000 | V36: 64675005 | W36: 59840978 | X36: 54586440 | Y36: 54268000 | Z36: 54268000 | AD36: Préstamos de largo plazo | AE36: =IFERROR(B36/B$33,0) | AF36: =IFERROR(C36/C$33,0) | AG36: =IFERROR(D36/D$33,0) | AH36: =IFERROR(E36/E$33,0) | AI36: =IFERROR(F36/F$33,0) | AJ36: =IFERROR(G36/G$33,0) | AK36: =IFERROR(H36/H$33,0) | AL36: =IFERROR(I36/I$33,0) | ... BE36: =IFERROR(AB36/AB$33,0) | BG36: Préstamos de largo plazo | BI36: =IFERROR(C36/B36-1,0) | BJ36: =IFERROR(D36/C36-1,0) | BK36: =IFERROR(E36/D36-1,0) | BL36: =IFERROR(F36/E36-1,0) | BM36: =IFERROR(G36/F36-1,0) | BN36: =IFERROR(H36/G36-1,0) | BO36: =IFERROR(I36/H36-1,0) | BP36: =IFERROR(J36/I36-1,0) | ... CH36: =IFERROR(AB36/AA36-1,0)
A37: Contribuciones por pagar | B37: 95000 | C37: 155000 | D37: 497000 | E37: 450000 | F37: 316000 | G37: 461000 | H37: 348000 | I37: 633000 | J37: 1021000 | K37: 1011000 | L37: 1552000 | M37: 1563000 | N37: 2074000 | O37: 2501000 | P37: 3168518 | Q37: 3433525.3 | R37: 2454000 | S37: 2876758.8 | T37: 3492117.8 | U37: 3121000 | V37: 3759750 | W37: 3441035.4 | X37: =4483008.93-X38 | Y37: 4668000 | Z37: 5417000 | AD37: Contribuciones por pagar | AE37: =IFERROR(B37/B$33,0) | AF37: =IFERROR(C37/C$33,0) | AG37: =IFERROR(D37/D$33,0) | AH37: =IFERROR(E37/E$33,0) | AI37: =IFERROR(F37/F$33,0) | AJ37: =IFERROR(G37/G$33,0) | AK37: =IFERROR(H37/H$33,0) | AL37: =IFERROR(I37/I$33,0) | ... BE37: =IFERROR(AB37/AB$33,0) | BG37: Contribuciones por pagar | BI37: =IFERROR(C37/B37-1,0) | BJ37: =IFERROR(D37/C37-1,0) | BK37: =IFERROR(E37/D37-1,0) | BL37: =IFERROR(F37/E37-1,0) | BM37: =IFERROR(G37/F37-1,0) | BN37: =IFERROR(H37/G37-1,0) | BO37: =IFERROR(I37/H37-1,0) | BP37: =IFERROR(J37/I37-1,0) | ... CH37: =IFERROR(AB37/AA37-1,0)
A38: Acreedores diversas y otras cuentas por pagar | B38: 185000 | C38: 310000 | D38: 335000 | E38: 505000 | F38: 41000 | G38: 229000 | H38: 356000 | I38: 80000 | J38: 62000 | K38: 223000 | L38: 31000 | M38: 398000 | N38: 585000 | O38: 600000 | P38: 645113 | Q38: 669184.7 | R38: 296000 | S38: 352413.85 | T38: 463869.94 | U38: 501000 | V38: 582334.27 | W38: 673578.63 | X38: 232951.49 | Y38: 398000 | Z38: 508000 | AD38: Acreedores diversas y otras cuentas por pagar | AE38: =IFERROR(B38/B$33,0) | AF38: =IFERROR(C38/C$33,0) | AG38: =IFERROR(D38/D$33,0) | AH38: =IFERROR(E38/E$33,0) | AI38: =IFERROR(F38/F$33,0) | AJ38: =IFERROR(G38/G$33,0) | AK38: =IFERROR(H38/H$33,0) | AL38: =IFERROR(I38/I$33,0) | ... BE38: =IFERROR(AB38/AB$33,0) | BG38: Acreedores diversas y otras cuentas por pagar | BI38: =IFERROR(C38/B38-1,0) | BJ38: =IFERROR(D38/C38-1,0) | BK38: =IFERROR(E38/D38-1,0) | BL38: =IFERROR(F38/E38-1,0) | BM38: =IFERROR(G38/F38-1,0) | BN38: =IFERROR(H38/G38-1,0) | BO38: =IFERROR(I38/H38-1,0) | BP38: =IFERROR(J38/I38-1,0) | ... CH38: =IFERROR(AB38/AA38-1,0)
A39: Aportaciones para futuros aumentos de capital como pasivos | B39: 0 | C39: 0 | D39: 0 | E39: 0 | F39: 0 | G39: 0 | H39: 0 | I39: 0 | J39: 2250000 | K39: 0 | L39: 0 | M39: 0 | N39: 0 | O39: 0 | R39: 0 | S39: 0 | T39: 0 | U39: 0 | V39: 0 | W39: 0 | X39: 0 | Y39: 0 | AD39: Aportaciones para futuros aumentos de capital como pasivos | AE39: =IFERROR(B39/B$33,0) | AF39: =IFERROR(C39/C$33,0) | AG39: =IFERROR(D39/D$33,0) | AH39: =IFERROR(E39/E$33,0) | AI39: =IFERROR(F39/F$33,0) | AJ39: =IFERROR(G39/G$33,0) | AK39: =IFERROR(H39/H$33,0) | AL39: =IFERROR(I39/I$33,0) | ... BE39: =IFERROR(AB39/AB$33,0) | BG39: Aportaciones para futuros aumentos de capital como pasivos | BI39: =IFERROR(C39/B39-1,0) | BJ39: =IFERROR(D39/C39-1,0) | BK39: =IFERROR(E39/D39-1,0) | BL39: =IFERROR(F39/E39-1,0) | BM39: =IFERROR(G39/F39-1,0) | BN39: =IFERROR(H39/G39-1,0) | BO39: =IFERROR(I39/H39-1,0) | BP39: =IFERROR(J39/I39-1,0) | ... CH39: =IFERROR(AB39/AA39-1,0)
A40: Pasivo por impuestos a la utilidad | B40: 44000 | C40: 120000 | D40: 88000 | E40: 44000 | F40: 92000 | G40: 71000 | H40: 164000 | I40: 270000 | J40: 211000 | K40: 294000 | L40: 1094000 | M40: 1114000 | N40: 1485000 | O40: 1900000 | P40: 2355861 | Q40: 2720411.4 | R40: 2744000 | S40: 3021912.8 | T40: 3340183.9 | U40: 3268000 | V40: 3726144.4 | W40: 3808299.5 | X40: 4221362 | Y40: 4732000 | Z40: 5272000 | AD40: Pasivo por impuestos a la utilidad | AE40: =IFERROR(B40/B$33,0) | AF40: =IFERROR(C40/C$33,0) | AG40: =IFERROR(D40/D$33,0) | AH40: =IFERROR(E40/E$33,0) | AI40: =IFERROR(F40/F$33,0) | AJ40: =IFERROR(G40/G$33,0) | AK40: =IFERROR(H40/H$33,0) | AL40: =IFERROR(I40/I$33,0) | ... BE40: =IFERROR(AB40/AB$33,0) | BG40: Pasivo por impuestos a la utilidad | BI40: =IFERROR(C40/B40-1,0) | BJ40: =IFERROR(D40/C40-1,0) | BK40: =IFERROR(E40/D40-1,0) | BL40: =IFERROR(F40/E40-1,0) | BM40: =IFERROR(G40/F40-1,0) | BN40: =IFERROR(H40/G40-1,0) | BO40: =IFERROR(I40/H40-1,0) | BP40: =IFERROR(J40/I40-1,0) | ... CH40: =IFERROR(AB40/AA40-1,0)
A41: Pasivo por Beneficios a Empleados | B41: 0 | C41: 0 | D41: 0 | E41: 185000 | F41: 185000 | G41: 185000 | H41: 0 | I41: 232000 | J41: 368000 | K41: 506000 | L41: 653000 | M41: 707000 | N41: 755000 | O41: 1185000 | P41: 1038792 | Q41: 1094502.7 | R41: 1152000 | S41: 1207415.1 | T41: 1265752.7 | U41: 1158000 | V41: 1060969.9 | W41: 965640.63 | X41: 757993.75 | Y41: 792000 | Z41: 826000 | AD41: Pasivo por Beneficios a Empleados | AE41: =IFERROR(B41/B$33,0) | AF41: =IFERROR(C41/C$33,0) | AG41: =IFERROR(D41/D$33,0) | AH41: =IFERROR(E41/E$33,0) | AI41: =IFERROR(F41/F$33,0) | AJ41: =IFERROR(G41/G$33,0) | AK41: =IFERROR(H41/H$33,0) | AL41: =IFERROR(I41/I$33,0) | ... BE41: =IFERROR(AB41/AB$33,0) | BG41: Pasivo por Beneficios a Empleados | BI41: =IFERROR(C41/B41-1,0) | BJ41: =IFERROR(D41/C41-1,0) | BK41: =IFERROR(E41/D41-1,0) | BL41: =IFERROR(F41/E41-1,0) | BM41: =IFERROR(G41/F41-1,0) | BN41: =IFERROR(H41/G41-1,0) | BO41: =IFERROR(I41/H41-1,0) | BP41: =IFERROR(J41/I41-1,0) | ... CH41: =IFERROR(AB41/AA41-1,0)
...

Sheet Efs OG
