Workbook

Sheet Ficha Contractual
B4: FICHA CONTRACTUAL
B5: Completar al inicio y actualizar ante cualquier modificación
B7: A. DATOS GENERALES DEL CRÉDITO
B8: Acreditado | C8: Red Girasol | D8: ID del Contrato | E8: 2025LP0007
B9: Razón Social | C9: RED GIRASOL SAPI DE CV | D9: Fecha de Firma | E9: 45715
B10: RFC | C10: RGI160414TR9 | D10: Fecha de 1ª disposición | E10: 45723
B11: Tipo de crédito | C11: Simple | D11: Fecha Vencimiento | E11: =EDATE(E10,C13) -> 46819
B12: Monto original (MXN) | C12: 50000000 | D12: Sindicado (si aplica) | E12: No
B13: Plazo (meses) | C13: 36 | D13: Periodicidad de pago capital | E13: Mensual, Despues de 6 meses calendario a partir de la fecha de la primera Disposición
B14: Tasa base | C14: 0.205 | D14: Administrador Maestro | E14: CXC
B15: Tipo de tasa | C15: FIJA | D15: Número de fideicomiso | E15: Fideicomiso - 1403
B17: B. COVENANTS — LÍMITES Y NIVELES DE INCUMPLIMIENTO
B18: Nivel I: Ajustes generales en covenants |Nivel II: Ajuste de tasa +1% y aforo sube a 1.50x | Nivel III: Evento de aceleración
B19: Covenant | C19: Fórmula Modelo Monitoreo | D19: Base | E19: Post-ajuste Nivel I | F19: Post-ajuste Nivel II
B20: COVENANTS ESTÁNDAR (aplican a todos los créditos)
B21: Rentabilidad Operativa | C21: (Gtos venta + Gtos admin + Gtos operación) / (Intereses cobrados + Comisiones cobradas) | D21: 0.29 | E21: 0.25 | F21: 0.29
B22: Cobertura de Deuda | C22: Activos productivos / Pasivos totales [Activos prod. = Bancos + Inversiones + Cartera] | D22: 1 | E22: 1.15 | F22: 1.07
B23: Cartera Vencida Neta | C23: (Cartera Vencida − Reservas) / (Cartera Vigente + Cartera Vencida) | D23: 0.05 | E23: 0.05 | F23: 0.1
B24: Capitalización | C24: (Cartera crédito neta) / Capital Contable Elegible | D24: 0.11 | E24: 0.25 | F24: 0.2
B25: Estimación preventiva de riesgos | C25: Reservas / Cartera vencida | D25: 1 | E25: 1 | F25: 0.8
B26: Coeficiente de liquidez | C26: (Efectivo + Inversiones disponibles + Cobranza programada) / Vencimientos deuda programados | D26: 1.1x | E26: 1.1x | F26: 1.0x
B27: COVENANTS ESPECÍFICOS DEL CONTRATO
B28: IMOR 16 | C28: Cartera vencida 16m / Portafolio 16m | D28: ≤ 7.5% | E28: ≤ 7.5% | F28: TBA
B29: Índice de apalancamiento | C29: Pasivo Total/ Capital Contable Ajustado | D29: ≤ 6.0 | E29: ≤ 5.0 | F29: TBA
B30: Índice de apalancamiento ajustado | C30: Pasivo Total / Derechos de Cobro sobre Participaciones | D30: ≤ 90% | E30: ≤ 85% | F30: TBA
B31: Índice de capitalización | C31: Capital Contable Ajustado / Activo Total | D31: ≥ 13% | E31: ≥ 15% | F31: TBA
B32: Índice de cartera atrasada | C32: Cartera Atrasada / Valor del Portafolio | D32: ≤ 11% | E32: ≤ 11% | F32: TBA
B33: Índice de cartera vencida | C33: Cartera Vencida/ Valor del Portafolio | D33: ≤ 14% | E33: ≤ 14% | F33: TBA
B34: Índice de rendimiento | C34: Ingresos Agregados / Valor del Portafolio | D34: ≥ 28% | E34: ≥ 30% | F34: TBA
B35: Índice de rentabilidad | C35: Utilidad Neta / Valor del Portafolio | D35: ≥ -2% | E35: ≥ 0% | F35: TBA
B36: Aforo mínimo | C36: Ver fórmula completa en pestaña EEFF — CTO A | D36: ≥ 1.35x | E36: ≥ 1.50x* | F36: TBA
B37: * El aforo aplicable cambia a 1.50x ante incumplimiento del escenario base de IMOR 16 (IMOR 16 > 7.5%)
B39: C. EVENTOS DE INCUMPLIMIENTO — CONSECUENCIAS POR NIVEL
B40: Nivel | C40: Descripción | D40: Consecuencias contractuales | G40: Fecha de activación
B41: Nivel I | C41: Incumplimiento de Niveles I de los covenants | D41: Ajustes en las condiciones generales de los covenants base | G41: 45870
B42: Nivel II | C42: Incumplimiento de Niveles II de los covenants | D42: Ajuste de tasa de interés +1% sobre la tasa vigente. Aforo mínimo requerido sube a 1.50x. | G42: [Fecha]
B43: [Otro evento] | C43: [Describir el evento de incumplimiento adicional según el contrato] | D43: Se considera Evento de Aceleración. El acreditante puede exigir el pago anticipado de la totalidad del crédito. | G43: [Fecha]
B45: D. DEFINICIONES CONTRACTUALES CLAVE
B46: Concepto | C46: Definición resumida
B47: Cartera Vigente | C47: Créditos al corriente sin días de atraso.
...

Sheet Obligaciones
B4: OBLIGACIONES DE HACER Y NO HACER
B5: Documento informativo · Adjuntar al correo de solicitud del certificado de cumplimiento trimestral
B7: Este documento es un resumen ejecutivo sobre las obligaciones contractuales. Las obligaciones completas, sus definiciones y consecuencias de incumplimiento constan en el Contrato de Crédito respectivo.
B9: I. OBLIGACIONES DE HACER
B10: # | C10: Obligación | D10: Frecuencia / Plazo
B11: 1 | C11: Entregar balances y estados de resultados internos mensuales dentro de los 15 días posteriores al cierre de cada mes. | D11: Mensual — día 15
B12: 2 | C12: Proporcionar estados financieros auditados por un contador independiente dentro de los 120 días siguientes al cierre del ejercicio fiscal. | D12: Anual — Hasta 120 días
B13: 3 | C13: Entregar, junto con la información financiera, un certificado que acredite el cumplimiento de las obligaciones financieras y la inexistencia de incumplimientos. | D13: Mensual — día 15
B14: 4 | C14: Mantener una conexión en tiempo real entre sus sistemas contables y de cobranza con el Agente Administrativo y el Administrador Maestro. Que permitan al agente administrativo el acceso en todo momento a la información relacionada con los Derecho de Cobro Transmitidos | D14: Continua
B15: 5 | C15: Informar al Agente Administrativo sobre cualquier "Efecto Adverso de Importancia" o incumplimiento en un plazo máximo de 5 días hábiles. | D15: Inmediato al evento
B16: 6 | C16: Notificar sobre litigios cuya cuantía exceda los $5,000,000.00 MXN o multas impuestas por autoridades que superen dicho umbral. | D16: Inmediato al evento
B17: 7 | C17: Observar todas las leyes aplicables (especialmente LRITF, LTOSF y LPDUSF), así como presentar y pagar impuestos de manera oportuna. | D17: Continua
B18: 8 | C18: Realizar todos los actos necesarios para transmitir los Derechos de Cobro al Patrimonio del Fideicomiso y mantener vigente el Contrato de Factoraje. | D18: Continua
B19: 9 | C19: Mantener covenants financieros dentro de los límites del contrato. | D19: Mensual
B20: 10 | C20: Permitir al Agente Administrativo auditar sus bienes y libros con un aviso previo de 5 días. | D20: A Solicitud
B21: 11 | C21: Mantener en el fideicomiso el monto necesario para cubrir capital e intereses de la siguiente fecha de pago. | D21: Continua
B23: II. OBLIGACIONES DE NO HACER
B24: # | C24: Restricción | D24: Condiciones / Excepciones
B25: 1 | C25: No contratar nueva deuda, salvo la ya existente o aquella que no cause incumplimiento en sus obligaciones financieras. | D25: Con autorización escrita previa
B26: 2 | C26: No otorgar garantías a favor de terceros o constituir gravámenes sobre sus activos (especialmente sobre los que forman parte del patrimonio del fideicomiso). | D26: Ver covenants de capitalización y cobertura
B27: 3 | C27: No realizar fusiones, escisiones, disoluciones o ventas de activos sustanciales, ni cambiar la naturaleza de su negocio. | D27: Ver condiciones específicas del contrato
B28: 4 | C28: No distribuir dividendos si esto resulta en un incumplimiento de sus obligaciones bajo los Documentos del Crédito. | D28: Ver condiciones específicas del contrato
B29: 5 | C29: No realizar pagos extraordinarios de salarios o bonos a accionistas o funcionarios fuera de términos de mercado o que afecten los límites financieros. | D29: Ver condiciones específicas del contrato
B30: 6 | C30: No realizar un "Cambio de Control" (perder el control o bajar del 50% de los valores representativos de capital). | D30: Ver condiciones específicas del contrato
B31: 7 | C31: No modificar sus políticas de otorgamiento de crédito o los formatos de contratos con sus clientes (Contratos de Crédito Red Girasol) sin autorización. | D31: Ver condiciones específicas del contrato
B32: 8 | C32: No Participar en actividades ilícitas, producción de armas, tabaco, juegos de azar o aquellas que dañen el medio ambiente.
B33: 9 | C33: No permitir que otras obligaciones quirografarias tengan mayor preferencia de pago que el crédito presente.

Sheet Supuestos
A1: MODELO
A2: Inicio Crédito Syscap | B2: Dic-24 | C2: Cuentas por cobrar, neto | D2: 0
A3: Disp. Inicial | B3: 5000000 | C3: Pagos anticipados y otros activos, neto | D3: 1500000
A4: Cobranza | B4: 0.9 | C4: Propiedades, mobiliario y equipo, neto | D4: 200000
A5: Crecimiento Cartera | B5: 0.0075 | C5: CAPITALIZACIÓN | D5: 20000000
A6: Crecimiento Gastos | B6: 0.06 | C6: Castigo Tasa Activa | D6: 0.015
A8: CARTERA
A9: # de Registros | B9: =COUNT(#REF!) -> 0 | C9: Días de Atraso Vencimientos | D9: 90
A10: Primer Crédito | B10: =MIN(#REF!)-DAY(MIN(#REF!))+1 -> #REF! | C10: Participación Histórica | D10: 0.01
A11: Tasa Activa Ponderada | B11: =SUMPRODUCT(#REF!,#REF!) -> #REF! | C11: Inicio Com. Apertura | D11: 44986
A12: Fecha LT | B12: 45657
A13: COMISIONES
A14: Tipo Producto | B14: Preoriginación | C14: Contratación | D14: Administración | E14: Notas
A15: Verde | B15: 0.02 | C15: 0.06 | D15: 0 | E15: Antes del 1 de Enero 2023
A16: Verde+ | B16: 0.02 | C16: 0 | D16: 0.01 | E16: Entre 01/01/23 y 01/01/24 - SOBRE EL SALDO INSOLUTO
A17: Crédito Automotriz | B17: 0.02 | C17: 0.015 | D17: 0.011 | E17: A partir del 2024
A18: Crédito Personal | B18: 0.02 | C18: 0.02 | D18: 0.0135 | E18: A partir del 2024
A19: Crédito PYME | B19: 0.02 | C19: 0.015 | D19: 0.011 | E19: A partir del 2024
A20: Crédito Solar | B20: 0.02 | C20: 0.01 | D20: 0.0085 | E20: A partir del 2024
A21: Comisión Éxito Vieja | B21: 0.02 | E21: Sobre cobranza total (intereses y amortizaciones)
A22: Comisión Éxito Nueva | B22: 0.1 | C22: Desde | D22: 45536 | E22: Sobre intereses a partir de Sep. 2024

Sheet Crédito Syscap
A1: Mes | B1: Saldo Inicial | C1: Disposiciones | D1: Pago | E1: Interés | F1: Amortización | G1: Saldo Final | H1: Comisión Estr | I1: Comisión Admin | J1: Total Comisiones
A2: 0 | B2: 0 | C2: 20000000
A3: 1 | B3: =C2 -> 20000000 | C3: 15000000 | D3: =IF(A3<=$B$45, E3, IF(B3>0, B3*(($B$40/12)/(1-(1+($B$40/12))^(-($B$44-A3+1)))), 0)) -> 350000 | E3: =B3*$B$40/12 -> 350000 | F3: =IF(A3<=$B$45, 0, D3-E3) -> 0 | G3: =B3-F3 -> 20000000 | H3: =C2*$B$47 -> 400000 | I3: =($B$42*$B$48/12) -> 20833.333 | J3: =H3+I3 -> 420833.33
A4: 2 | B4: =G3+C3 -> 35000000 | C4: 15000000 | D4: =IF(A4<=$B$45, E4, IF(B4>0, B4*(($B$40/12)/(1-(1+($B$40/12))^(-($B$44-A4+1)))), 0)) -> 612500 | E4: =B4*$B$40/12 -> 612500 | F4: =IF(A4<=$B$45, 0, D4-E4) -> 0 | G4: =B4-F4 -> 35000000 | H4: =C3*$B$47 -> 300000 | I4: =($B$42*$B$48/12) -> 20833.333 | J4: =H4+I4 -> 320833.33
A5: 3 | B5: =G4+C4 -> 50000000 | C5: 0 | D5: =IF(A5<=$B$45, E5, IF(B5>0, B5*(($B$40/12)/(1-(1+($B$40/12))^(-($B$44-A5+1)))), 0)) -> 875000 | E5: =B5*$B$40/12 -> 875000 | F5: =IF(A5<=$B$45, 0, D5-E5) -> 0 | G5: =B5-F5 -> 50000000 | H5: =C4*$B$47 -> 300000 | I5: =($B$42*$B$48/12) -> 20833.333 | J5: =H5+I5 -> 320833.33
A6: 4 | B6: =G5+C5 -> 50000000 | C6: 0 | D6: =IF(A6<=$B$45, E6, IF(B6>0, B6*(($B$40/12)/(1-(1+($B$40/12))^(-($B$44-A6+1)))), 0)) -> 875000 | E6: =B6*$B$40/12 -> 875000 | F6: =IF(A6<=$B$45, 0, D6-E6) -> 0 | G6: =B6-F6 -> 50000000 | H6: =C5*$B$47 -> 0 | I6: =($B$42*$B$48/12) -> 20833.333 | J6: =H6+I6 -> 20833.333
A7: 5 | B7: =G6+C6 -> 50000000 | C7: 0 | D7: =IF(A7<=$B$45, E7, IF(B7>0, B7*(($B$40/12)/(1-(1+($B$40/12))^(-($B$44-A7+1)))), 0)) -> 875000 | E7: =B7*$B$40/12 -> 875000 | F7: =IF(A7<=$B$45, 0, D7-E7) -> 0 | G7: =B7-F7 -> 50000000 | H7: =C6*$B$47 -> 0 | I7: =($B$42*$B$48/12) -> 20833.333 | J7: =H7+I7 -> 20833.333
A8: 6 | B8: =G7+C7 -> 50000000 | C8: 0 | D8: =IF(A8<=$B$45, E8, IF(B8>0, B8*(($B$40/12)/(1-(1+($B$40/12))^(-($B$44-A8+1)))), 0)) -> 875000 | E8: =B8*$B$40/12 -> 875000 | F8: =IF(A8<=$B$45, 0, D8-E8) -> 0 | G8: =B8-F8 -> 50000000 | H8: =C7*$B$47 -> 0 | I8: =($B$42*$B$48/12) -> 20833.333 | J8: =H8+I8 -> 20833.333
A9: 7 | B9: =G8+C8 -> 50000000 | C9: 0 | D9: =IF(A9<=$B$45, E9, IF(B9>0, B9*(($B$40/12)/(1-(1+($B$40/12))^(-($B$44-A9+1)))), 0)) -> 2156487.7 | E9: =B9*$B$40/12 -> 875000 | F9: =IF(A9<=$B$45, 0, D9-E9) -> 1281487.7 | G9: =B9-F9 -> 48718512 | H9: =C8*$B$47 -> 0 | I9: =($B$42*$B$48/12) -> 20833.333 | J9: =H9+I9 -> 20833.333
A10: 8 | B10: =G9+C9 -> 48718512 | C10: 0 | D10: =IF(A10<=$B$45, E10, IF(B10>0, B10*(($B$40/12)/(1-(1+($B$40/12))^(-($B$44-A10+1)))), 0)) -> 2156487.7 | E10: =B10*$B$40/12 -> 852573.96 | F10: =IF(A10<=$B$45, 0, D10-E10) -> 1303913.8 | G10: =B10-F10 -> 47414598 | H10: =C9*$B$47 -> 0 | I10: =($B$42*$B$48/12) -> 20833.333 | J10: =H10+I10 -> 20833.333
A11: 9 | B11: =G10+C10 -> 47414598 | C11: 0 | D11: =IF(A11<=$B$45, E11, IF(B11>0, B11*(($B$40/12)/(1-(1+($B$40/12))^(-($B$44-A11+1)))), 0)) -> 2156487.7 | E11: =B11*$B$40/12 -> 829755.47 | F11: =IF(A11<=$B$45, 0, D11-E11) -> 1326732.3 | G11: =B11-F11 -> 46087866 | H11: =C10*$B$47 -> 0 | I11: =($B$42*$B$48/12) -> 20833.333 | J11: =H11+I11 -> 20833.333
A12: 10 | B12: =G11+C11 -> 46087866 | D12: =IF(A12<=$B$45, E12, IF(B12>0, B12*(($B$40/12)/(1-(1+($B$40/12))^(-($B$44-A12+1)))), 0)) -> 2156487.7 | E12: =B12*$B$40/12 -> 806537.66 | F12: =IF(A12<=$B$45, 0, D12-E12) -> 1349950.1 | G12: =B12-F12 -> 44737916 | H12: =C11*$B$47 -> 0 | I12: =($B$42*$B$48/12) -> 20833.333 | J12: =H12+I12 -> 20833.333
A13: 11 | B13: =G12+C12 -> 44737916 | D13: =IF(A13<=$B$45, E13, IF(B13>0, B13*(($B$40/12)/(1-(1+($B$40/12))^(-($B$44-A13+1)))), 0)) -> 2156487.7 | E13: =B13*$B$40/12 -> 782913.53 | F13: =IF(A13<=$B$45, 0, D13-E13) -> 1373574.2 | G13: =B13-F13 -> 43364342 | H13: =C12*$B$47 -> 0 | I13: =($B$42*$B$48/12) -> 20833.333 | J13: =H13+I13 -> 20833.333
A14: 12 | B14: =G13+C13 -> 43364342 | D14: =IF(A14<=$B$45, E14, IF(B14>0, B14*(($B$40/12)/(1-(1+($B$40/12))^(-($B$44-A14+1)))), 0)) -> 2156487.7 | E14: =B14*$B$40/12 -> 758875.98 | F14: =IF(A14<=$B$45, 0, D14-E14) -> 1397611.8 | G14: =B14-F14 -> 41966730 | H14: =C13*$B$47 -> 0 | I14: =($B$42*$B$48/12) -> 20833.333 | J14: =H14+I14 -> 20833.333
A15: 13 | B15: =G14+C14 -> 41966730 | D15: =IF(A15<=$B$45, E15, IF(B15>0, B15*(($B$40/12)/(1-(1+($B$40/12))^(-($B$44-A15+1)))), 0)) -> 2156487.7 | E15: =B15*$B$40/12 -> 734417.78 | F15: =IF(A15<=$B$45, 0, D15-E15) -> 1422070 | G15: =B15-F15 -> 40544660 | H15: =C14*$B$47 -> 0 | I15: =($B$42*$B$48/12) -> 20833.333 | J15: =H15+I15 -> 20833.333
A16: 14 | B16: =G15+C15 -> 40544660 | D16: =IF(A16<=$B$45, E16, IF(B16>0, B16*(($B$40/12)/(1-(1+($B$40/12))^(-($B$44-A16+1)))), 0)) -> 2156487.7 | E16: =B16*$B$40/12 -> 709531.55 | F16: =IF(A16<=$B$45, 0, D16-E16) -> 1446956.2 | G16: =B16-F16 -> 39097704 | H16: =C15*$B$47 -> 0 | I16: =($B$42*$B$48/12) -> 20833.333 | J16: =H16+I16 -> 20833.333
A17: 15 | B17: =G16+C16 -> 39097704 | D17: =IF(A17<=$B$45, E17, IF(B17>0, B17*(($B$40/12)/(1-(1+($B$40/12))^(-($B$44-A17+1)))), 0)) -> 2156487.7 | E17: =B17*$B$40/12 -> 684209.82 | F17: =IF(A17<=$B$45, 0, D17-E17) -> 1472277.9 | G17: =B17-F17 -> 37625426 | H17: =C16*$B$47 -> 0 | I17: =($B$42*$B$48/12) -> 20833.333 | J17: =H17+I17 -> 20833.333
A18: 16 | B18: =G17+C17 -> 37625426 | D18: =IF(A18<=$B$45, E18, IF(B18>0, B18*(($B$40/12)/(1-(1+($B$40/12))^(-($B$44-A18+1)))), 0)) -> 2156487.7 | E18: =B18*$B$40/12 -> 658444.96 | F18: =IF(A18<=$B$45, 0, D18-E18) -> 1498042.8 | G18: =B18-F18 -> 36127383 | H18: =C17*$B$47 -> 0 | I18: =($B$42*$B$48/12) -> 20833.333 | J18: =H18+I18 -> 20833.333
A19: 17 | B19: =G18+C18 -> 36127383 | D19: =IF(A19<=$B$45, E19, IF(B19>0, B19*(($B$40/12)/(1-(1+($B$40/12))^(-($B$44-A19+1)))), 0)) -> 2156487.7 | E19: =B19*$B$40/12 -> 632229.21 | F19: =IF(A19<=$B$45, 0, D19-E19) -> 1524258.5 | G19: =B19-F19 -> 34603125 | H19: =C18*$B$47 -> 0 | I19: =($B$42*$B$48/12) -> 20833.333 | J19: =H19+I19 -> 20833.333
A20: 18 | B20: =G19+C19 -> 34603125 | D20: =IF(A20<=$B$45, E20, IF(B20>0, B20*(($B$40/12)/(1-(1+($B$40/12))^(-($B$44-A20+1)))), 0)) -> 2156487.7 | E20: =B20*$B$40/12 -> 605554.68 | F20: =IF(A20<=$B$45, 0, D20-E20) -> 1550933.1 | G20: =B20-F20 -> 33052192 | H20: =C19*$B$47 -> 0 | I20: =($B$42*$B$48/12) -> 20833.333 | J20: =H20+I20 -> 20833.333
A21: 19 | B21: =G20+C20 -> 33052192 | D21: =IF(A21<=$B$45, E21, IF(B21>0, B21*(($B$40/12)/(1-(1+($B$40/12))^(-($B$44-A21+1)))), 0)) -> 2156487.7 | E21: =B21*$B$40/12 -> 578413.35 | F21: =IF(A21<=$B$45, 0, D21-E21) -> 1578074.4 | G21: =B21-F21 -> 31474117 | H21: =C20*$B$47 -> 0 | I21: =($B$42*$B$48/12) -> 20833.333 | J21: =H21+I21 -> 20833.333
A22: 20 | B22: =G21+C21 -> 31474117 | D22: =IF(A22<=$B$45, E22, IF(B22>0, B22*(($B$40/12)/(1-(1+($B$40/12))^(-($B$44-A22+1)))), 0)) -> 2156487.7 | E22: =B22*$B$40/12 -> 550797.05 | F22: =IF(A22<=$B$45, 0, D22-E22) -> 1605690.7 | G22: =B22-F22 -> 29868427 | H22: =C21*$B$47 -> 0 | I22: =($B$42*$B$48/12) -> 20833.333 | J22: =H22+I22 -> 20833.333
A23: 21 | B23: =G22+C22 -> 29868427 | D23: =IF(A23<=$B$45, E23, IF(B23>0, B23*(($B$40/12)/(1-(1+($B$40/12))^(-($B$44-A23+1)))), 0)) -> 2156487.7 | E23: =B23*$B$40/12 -> 522697.46 | F23: =IF(A23<=$B$45, 0, D23-E23) -> 1633790.3 | G23: =B23-F23 -> 28234636 | H23: =C22*$B$47 -> 0 | I23: =($B$42*$B$48/12) -> 20833.333 | J23: =H23+I23 -> 20833.333
... A38: 36 | B38: =G37+C37 -> 2119398.3 | D38: =IF(A38<=$B$45, E38, IF(B38>0, B38*(($B$40/12)/(1-(1+($B$40/12))^(-($B$44-A38+1)))), 0)) -> 2156487.7 | E38: =B38*$B$40/12 -> 37089.47 | F38: =IF(A38<=$B$45, 0, D38-E38) -> 2119398.3 | G38: =B38-F38 -> 1.1175871e-08 | H38: =C37*$B$47 -> 0 | I38: =($B$42*$B$48/12) -> 20833.333 | J38: =H38+I38 -> 20833.333
A40: Tasa | B40: 0.21
A41: Monto Disposiciones | B41: 10000000
A42: Saldo Total Línea | B42: 50000000
A43: Cantidad de Disp. | B43: 2
A44: Plazo | B44: 36
A45: Gracia de Capital | B45: 6
A46: Gastos Notariales | B46: 550000
A47: Comisión Estr. | B47: 0.02
A48: Comisión Admin. | B48: 0.005

Sheet Monitoreo
B2: IMOR 16
B3: 45657 | C3: =EOMONTH(B3,1) -> 45688 | D3: =EOMONTH(C3,1) -> 45716 | E3: =EOMONTH(D3,1) -> 45747 | F3: =EOMONTH(E3,1) -> 45777 | G3: =EOMONTH(F3,1) -> 45808 | H3: =EOMONTH(G3,1) -> 45838 | I3: =EOMONTH(H3,1) -> 45869 | J3: =EOMONTH(I3,1) -> 45900 | ... BJ3: =EOMONTH(BI3,1) -> 47483
A4: RL | B4: ='Efs Real'!L69 -> 0.051749426 | D4: ='Efs Real'!N69 -> 0.038760461 | E4: ='Efs Real'!O69 -> 0.037997795 | F4: ='Efs Real'!P69 -> 0.02464623 | G4: ='Efs Real'!Q69 -> 0.071112877 | H4: ='Efs Real'!R69 -> 0.074020122 | I4: ='Efs Real'!S69 -> 0.098921489 | J4: ='Efs Real'!T69 -> 0.11188499 | K4: ='Efs Real'!U69 -> 0.13215844 | ... P4: ='Efs Real'!Z69 -> 0.067340333
A5: MAX | B5: 0.075 | C5: 0.075 | D5: 0.075 | E5: 0.075 | F5: 0.075 | G5: 0.075 | H5: 0.075 | I5: 0.075 | J5: 0.075 | K5: 0.075 | L5: 0.075 | M5: 0.075 | N5: 0.075 | O5: 0.075 | P5: 0.075 | Q5: 0.075 | R5: 0.075 | S5: 0.075 | T5: 0.075 | U5: 0.075 | V5: 0.075 | W5: 0.075 | X5: 0.075 | Y5: 0.075 | Z5: 0.075 | AA5: 0.075 | AB5: 0.075 | AC5: 0.075 | AD5: 0.075 | AE5: 0.075 | AF5: 0.075 | AG5: 0.075 | AH5: 0.075 | AI5: 0.075 | AJ5: 0.075 | AK5: 0.075 | AL5: 0.075 | AM5: 0.075 | AN5: 0.075 | AO5: 0.075 | AP5: 0.075 | AQ5: 0.075 | AR5: 0.075 | AS5: 0.075 | AT5: 0.075 | AU5: 0.075 | AV5: 0.075 | AW5: 0.075 | AX5: 0.075 | AY5: 0.075 | AZ5: 0.075 | BA5: 0.075 | BB5: 0.075 | BC5: 0.075 | BD5: 0.075 | BE5: 0.075 | BF5: 0.075 | BG5: 0.075 | BH5: 0.075 | BI5: 0.075 | BJ5: 0.075
B7: Indice de apalancamiento
B8: 45657 | C8: =EOMONTH(B8,1) -> 45688 | D8: =EOMONTH(C8,1) -> 45716 | E8: =EOMONTH(D8,1) -> 45747 | F8: =EOMONTH(E8,1) -> 45777 | G8: =EOMONTH(F8,1) -> 45808 | H8: =EOMONTH(G8,1) -> 45838 | I8: =EOMONTH(H8,1) -> 45869 | J8: =EOMONTH(I8,1) -> 45900 | ... BJ8: =EOMONTH(BI8,1) -> 47483
A9: OG | B9: ='Efs OG'!CS84 -> 0.79734677 | C9: ='Efs OG'!CT84 -> 0.79016044 | D9: ='Efs OG'!CU84 -> 2.058031 | E9: ='Efs OG'!CV84 -> 2.9822117 | F9: ='Efs OG'!CW84 -> 4.9712842 | G9: ='Efs OG'!CX84 -> 5.5084033 | H9: ='Efs OG'!CY84 -> 5.8675784 | I9: ='Efs OG'!CZ84 -> 5.4374108 | ... BJ9: ='Efs OG'!FA84 -> 0.040826053
A10: RL | B10: ='Efs Real'!L57 -> 1.0218305 | C10: ='Efs Real'!M57 -> 1.1200474 | D10: ='Efs Real'!N57 -> 1.5228594 | E10: ='Efs Real'!O57 -> 3.142638 | F10: ='Efs Real'!P57 -> 3.2542372 | G10: ='Efs Real'!Q57 -> 4.3216202 | H10: ='Efs Real'!R57 -> 4.0454956 | I10: ='Efs Real'!S57 -> 5.2496795 | ... P10: ='Efs Real'!Z57 -> 14.334917
A11: MAX | B11: 6 | C11: 6 | D11: 6 | E11: 6 | F11: 6 | G11: 6 | H11: 6 | I11: 6 | J11: 5 | K11: 5 | L11: 5 | M11: 5 | N11: 5 | O11: 5 | P11: 5 | Q11: 5 | R11: 5 | S11: 5 | T11: 5 | U11: 5 | V11: 5 | W11: 5 | X11: 5 | Y11: 5 | Z11: 5 | AA11: 5 | AB11: 5 | AC11: 5 | AD11: 5 | AE11: 5 | AF11: 5 | AG11: 5 | AH11: 5 | AI11: 5 | AJ11: 5 | AK11: 5 | AL11: 5 | AM11: 5 | AN11: 5 | AO11: 5 | AP11: 5 | AQ11: 5 | AR11: 5 | AS11: 5 | AT11: 5 | AU11: 5 | AV11: 5 | AW11: 5 | AX11: 5 | AY11: 5 | AZ11: 5 | BA11: 5 | BB11: 5 | BC11: 5 | BD11: 5 | BE11: 5 | BF11: 5 | BG11: 5 | BH11: 5 | BI11: 5 | BJ11: 5
A13: =IFERROR(__xludf.DUMMYFUNCTION("IMPORTRANGE(""https://docs.google.com/spreadsheets/d/1RNG9c9ku9IgXbqzh4Ng5a6f84xmyVPd-/edit?usp=sharing&ouid=116612639875179195240&rtpof=true&sd=true"",""Efs Real!B1"")"),"#REF!") -> #REF! | B13: Indice de apalancamiento ajustado
A14: =IFERROR(__xludf.DUMMYFUNCTION("IMPORTRANGE(""https://docs.google.com/spreadsheets/d/1RNG9c9ku9IgXbqzh4Ng5a6f84xmyVPd-/edit?gid=1965519997#gid=1965519997"",""Efs Real!B:B"")"),"#REF!") -> #REF! | B14: 45657 | C14: =EOMONTH(B14,1) -> 45688 | D14: =EOMONTH(C14,1) -> 45716 | E14: =EOMONTH(D14,1) -> 45747 | F14: =EOMONTH(E14,1) -> 45777 | G14: =EOMONTH(F14,1) -> 45808 | H14: =EOMONTH(G14,1) -> 45838 | I14: =EOMONTH(H14,1) -> 45869 | J14: =EOMONTH(I14,1) -> 45900 | ... BJ14: =EOMONTH(BI14,1) -> 47483
A15: OG | B15: ='Efs OG'!CS85 -> 0.47790809 | C15: ='Efs OG'!CT85 -> 0.47263307 | D15: ='Efs OG'!CU85 -> 0.69852675 | E15: ='Efs OG'!CV85 -> 0.77055709 | F15: ='Efs OG'!CW85 -> 0.85295858 | G15: ='Efs OG'!CX85 -> 0.87179625 | H15: ='Efs OG'!CY85 -> 0.8861586 | I15: ='Efs OG'!CZ85 -> 0.88527086 | ... BJ15: ='Efs OG'!FA85 -> 0.049411608
A16: RL | B16: ='Efs Real'!L58 -> 0.54297135 | C16: ='Efs Real'!M58 -> 0.58188453 | D16: ='Efs Real'!N58 -> 0.64550829 | E16: ='Efs Real'!O58 -> 0.79824949 | F16: ='Efs Real'!P58 -> 0.82088828 | G16: ='Efs Real'!Q58 -> 0.91499578 | H16: ='Efs Real'!R58 -> 0.86940431 | I16: ='Efs Real'!S58 -> 0.87028633 | ... P16: ='Efs Real'!Z58 -> 1.0810481
A17: MAX | B17: 0.9 | C17: 0.9 | D17: 0.9 | E17: 0.9 | F17: 0.9 | G17: 0.9 | H17: 0.9 | I17: 0.9 | J17: 0.85 | K17: 0.85 | L17: 0.85 | M17: 0.85 | N17: 0.85 | O17: 0.85 | P17: 0.85 | Q17: 0.85 | R17: 0.85 | S17: 0.85 | T17: 0.85 | U17: 0.85 | V17: 0.85 | W17: 0.85 | X17: 0.85 | Y17: 0.85 | Z17: 0.85 | AA17: 0.85 | AB17: 0.85 | AC17: 0.85 | AD17: 0.85 | AE17: 0.85 | AF17: 0.85 | AG17: 0.85 | AH17: 0.85 | AI17: 0.85 | AJ17: 0.85 | AK17: 0.85 | AL17: 0.85 | AM17: 0.85 | AN17: 0.85 | AO17: 0.85 | AP17: 0.85 | AQ17: 0.85 | AR17: 0.85 | AS17: 0.85 | AT17: 0.85 | AU17: 0.85 | AV17: 0.85 | AW17: 0.85 | AX17: 0.85 | AY17: 0.85 | AZ17: 0.85 | BA17: 0.85 | BB17: 0.85 | BC17: 0.85 | BD17: 0.85 | BE17: 0.85 | BF17: 0.85 | BG17: 0.85 | BH17: 0.85 | BI17: 0.85 | BJ17: 0.85
B19: Indice de capitalizacion
B20: 45657 | C20: =EOMONTH(B20,1) -> 45688 | D20: =EOMONTH(C20,1) -> 45716 | E20: =EOMONTH(D20,1) -> 45747 | F20: =EOMONTH(E20,1) -> 45777 | G20: =EOMONTH(F20,1) -> 45808 | H20: =EOMONTH(G20,1) -> 45838 | I20: =EOMONTH(H20,1) -> 45869 | J20: =EOMONTH(I20,1) -> 45900 | ... BJ20: =EOMONTH(BI20,1) -> 47483
A21: OG | B21: ='Efs OG'!CS83 -> 0.56988345 | C21: ='Efs OG'!CT83 -> 0.56780842 | D21: ='Efs OG'!CU83 -> 0.32915346 | E21: ='Efs OG'!CV83 -> 0.2522785 | F21: ='Efs OG'!CW83 -> 0.16890552 | G21: ='Efs OG'!CX83 -> 0.15607544 | H21: ='Efs OG'!CY83 -> 0.14913754 | I21: ='Efs OG'!CZ83 -> 0.16072783 | ... BJ21: ='Efs OG'!FA83 -> 1.0277649
A22: RL | B22: ='Efs Real'!L60 -> 0.4946013 | C22: ='Efs Real'!M60 -> 0.47168758 | D22: ='Efs Real'!N60 -> 0.39637564 | E22: ='Efs Real'!O60 -> 0.24139208 | F22: ='Efs Real'!P60 -> 0.23505976 | G22: ='Efs Real'!Q60 -> 0.1879127 | H22: ='Efs Real'!R60 -> 0.19819363 | I22: ='Efs Real'!S60 -> 0.16000821 | ... P22: ='Efs Real'!Z60 -> 0.065212493
A23: MIN | B23: 0.13 | C23: 0.13 | D23: 0.13 | E23: 0.13 | F23: 0.13 | G23: 0.13 | H23: 0.13 | I23: 0.13 | J23: 0.15 | K23: 0.15 | L23: 0.15 | M23: 0.15 | N23: 0.15 | O23: 0.15 | P23: 0.15 | Q23: 0.15 | R23: 0.15 | S23: 0.15 | T23: 0.15 | U23: 0.15 | V23: 0.15 | W23: 0.15 | X23: 0.15 | Y23: 0.15 | Z23: 0.15 | AA23: 0.15 | AB23: 0.15 | AC23: 0.15 | AD23: 0.15 | AE23: 0.15 | AF23: 0.15 | AG23: 0.15 | AH23: 0.15 | AI23: 0.15 | AJ23: 0.15 | AK23: 0.15 | AL23: 0.15 | AM23: 0.15 | AN23: 0.15 | AO23: 0.15 | AP23: 0.15 | AQ23: 0.15 | AR23: 0.15 | AS23: 0.15 | AT23: 0.15 | AU23: 0.15 | AV23: 0.15 | AW23: 0.15 | AX23: 0.15 | AY23: 0.15 | AZ23: 0.15 | BA23: 0.15 | BB23: 0.15 | BC23: 0.15 | BD23: 0.15 | BE23: 0.15 | BF23: 0.15 | BG23: 0.15 | BH23: 0.15 | BI23: 0.15 | BJ23: 0.15
B25: Indice de cartera atrasada
B26: 45657 | C26: =EOMONTH(B26,1) -> 45688 | D26: =EOMONTH(C26,1) -> 45716 | E26: =EOMONTH(D26,1) -> 45747 | F26: =EOMONTH(E26,1) -> 45777 | G26: =EOMONTH(F26,1) -> 45808 | H26: =EOMONTH(G26,1) -> 45838 | I26: =EOMONTH(H26,1) -> 45869 | J26: =EOMONTH(I26,1) -> 45900 | ... BJ26: =EOMONTH(BI26,1) -> 47483
A27: RL | B27: ='Efs Real'!L79 -> 0.034638809 | D27: ='Efs Real'!N79 -> 0.1212076 | E27: ='Efs Real'!O79 -> 0.13826239 | F27: ='Efs Real'!P79 -> 0.078829252 | G27: ='Efs Real'!Q79 -> 0.047487779 | H27: ='Efs Real'!R79 -> 0.1025311 | I27: ='Efs Real'!S79 -> 0.092024709 | J27: ='Efs Real'!T79 -> 0.058130551 | K27: ='Efs Real'!U79 -> 0.1458566 | ... P27: ='Efs Real'!Z79 -> 0.034578491
A28: MAX | B28: 0.11 | C28: 0.11 | D28: 0.11 | E28: 0.11 | F28: 0.11 | G28: 0.11 | H28: 0.11 | I28: 0.11 | J28: 0.11 | K28: 0.11 | L28: 0.11 | M28: 0.11 | N28: 0.11 | O28: 0.11 | P28: 0.11 | Q28: 0.11 | R28: 0.11 | S28: 0.11 | T28: 0.11 | U28: 0.11 | V28: 0.11 | W28: 0.11 | X28: 0.11 | Y28: 0.11 | Z28: 0.11 | AA28: 0.11 | AB28: 0.11 | AC28: 0.11 | AD28: 0.11 | AE28: 0.11 | AF28: 0.11 | AG28: 0.11 | AH28: 0.11 | AI28: 0.11 | AJ28: 0.11 | AK28: 0.11 | AL28: 0.11 | AM28: 0.11 | AN28: 0.11 | AO28: 0.11 | AP28: 0.11 | AQ28: 0.11 | AR28: 0.11 | AS28: 0.11 | AT28: 0.11 | AU28: 0.11 | AV28: 0.11 | AW28: 0.11 | AX28: 0.11 | AY28: 0.11 | AZ28: 0.11 | BA28: 0.11 | BB28: 0.11 | BC28: 0.11 | BD28: 0.11 | BE28: 0.11 | BF28: 0.11 | BG28: 0.11 | BH28: 0.11 | BI28: 0.11 | BJ28: 0.11
B30: Indice de cartera vencida
B31: 45657 | C31: =EOMONTH(B31,1) -> 45688 | D31: =EOMONTH(C31,1) -> 45716 | E31: =EOMONTH(D31,1) -> 45747 | F31: =EOMONTH(E31,1) -> 45777 | G31: =EOMONTH(F31,1) -> 45808 | H31: =EOMONTH(G31,1) -> 45838 | I31: =EOMONTH(H31,1) -> 45869 | J31: =EOMONTH(I31,1) -> 45900 | ... BJ31: =EOMONTH(BI31,1) -> 47483
A32: RL | B32: ='Efs Real'!L78 -> 0.093519918 | D32: ='Efs Real'!N78 -> 0.10098074 | E32: ='Efs Real'!O78 -> 0.11312762 | F32: ='Efs Real'!P78 -> 0.098726512 | G32: ='Efs Real'!Q78 -> 0.12932795 | H32: ='Efs Real'!R78 -> 0.13336209 | I32: ='Efs Real'!S78 -> 0.14904247 | J32: ='Efs Real'!T78 -> 0.15850606 | K32: ='Efs Real'!U78 -> 0.1717627 | ... P32: ='Efs Real'!Z78 -> 0.16224649
A33: MAX | B33: 0.14 | C33: 0.14 | D33: 0.14 | E33: 0.14 | F33: 0.14 | G33: 0.14 | H33: 0.14 | I33: 0.14 | J33: 0.14 | K33: 0.14 | L33: 0.14 | M33: 0.14 | N33: 0.14 | O33: 0.14 | P33: 0.14 | Q33: 0.14 | R33: 0.14 | S33: 0.14 | T33: 0.14 | U33: 0.14 | V33: 0.14 | W33: 0.14 | X33: 0.14 | Y33: 0.14 | Z33: 0.14 | AA33: 0.14 | AB33: 0.14 | AC33: 0.14 | AD33: 0.14 | AE33: 0.14 | AF33: 0.14 | AG33: 0.14 | AH33: 0.14 | AI33: 0.14 | AJ33: 0.14 | AK33: 0.14 | AL33: 0.14 | AM33: 0.14 | AN33: 0.14 | AO33: 0.14 | AP33: 0.14 | AQ33: 0.14 | AR33: 0.14 | AS33: 0.14 | AT33: 0.14 | AU33: 0.14 | AV33: 0.14 | AW33: 0.14 | AX33: 0.14 | AY33: 0.14 | AZ33: 0.14 | BA33: 0.14 | BB33: 0.14 | BC33: 0.14 | BD33: 0.14 | BE33: 0.14 | BF33: 0.14 | BG33: 0.14 | BH33: 0.14 | BI33: 0.14 | BJ33: 0.14
B35: Indice de rendimiento
B36: 45657 | C36: =EOMONTH(B36,1) -> 45688 | D36: =EOMONTH(C36,1) -> 45716 | E36: =EOMONTH(D36,1) -> 45747 | F36: =EOMONTH(E36,1) -> 45777 | G36: =EOMONTH(F36,1) -> 45808 | H36: =EOMONTH(G36,1) -> 45838 | I36: =EOMONTH(H36,1) -> 45869 | J36: =EOMONTH(I36,1) -> 45900 | ... BJ36: =EOMONTH(BI36,1) -> 47483
A37: OG | B37: ='Efs OG'!CS86 -> 0.32465717 | C37: ='Efs OG'!CT86 -> 0.29792175 | D37: ='Efs OG'!CU86 -> 0.32148484 | E37: ='Efs OG'!CV86 -> 0.31382425 | F37: ='Efs OG'!CW86 -> 0.30921444 | G37: ='Efs OG'!CX86 -> 0.29454936 | H37: ='Efs OG'!CY86 -> 0.29457407 | I37: ='Efs OG'!CZ86 -> 0.29565668 | ... BJ37: ='Efs OG'!FA86 -> 0.10914313
A38: RL | B38: ='Efs Real'!L61 -> 0.49128635 | D38: ='Efs Real'!N61 -> 0.46343952 | E38: ='Efs Real'!O61 -> 0.40301369 | F38: ='Efs Real'!P61 -> 0.34426087 | G38: ='Efs Real'!Q61 -> 0.33571751 | H38: ='Efs Real'!R61 -> 0.31486238 | I38: ='Efs Real'!S61 -> 0.28804192 | J38: ='Efs Real'!T61 -> 0.25722046 | K38: ='Efs Real'!U61 -> 0.25859564 | ... P38: ='Efs Real'!Z61 -> 0.16607488
A39: MIN | B39: 0.28 | C39: 0.28 | D39: 0.28 | E39: 0.28 | F39: 0.28 | G39: 0.28 | H39: 0.28 | I39: 0.28 | J39: 0.3 | K39: 0.3 | L39: 0.3 | M39: 0.3 | N39: 0.3 | O39: 0.3 | P39: 0.3 | Q39: 0.3 | R39: 0.3 | S39: 0.3 | T39: 0.3 | U39: 0.3 | V39: 0.3 | W39: 0.3 | X39: 0.3 | Y39: 0.3 | Z39: 0.3 | AA39: 0.3 | AB39: 0.3 | AC39: 0.3 | AD39: 0.3 | AE39: 0.3 | AF39: 0.3 | AG39: 0.3 | AH39: 0.3 | AI39: 0.3 | AJ39: 0.3 | AK39: 0.3 | AL39: 0.3 | AM39: 0.3 | AN39: 0.3 | AO39: 0.3 | AP39: 0.3 | AQ39: 0.3 | AR39: 0.3 | AS39: 0.3 | AT39: 0.3 | AU39: 0.3 | AV39: 0.3 | AW39: 0.3 | AX39: 0.3 | AY39: 0.3 | AZ39: 0.3 | BA39: 0.3 | BB39: 0.3 | BC39: 0.3 | BD39: 0.3 | BE39: 0.3 | BF39: 0.3 | BG39: 0.3 | BH39: 0.3 | BI39: 0.3 | BJ39: 0.3
B41: Indice rentabilidad
B42: 45657 | C42: =EOMONTH(B42,1) -> 45688 | D42: =EOMONTH(C42,1) -> 45716 | E42: =EOMONTH(D42,1) -> 45747 | F42: =EOMONTH(E42,1) -> 45777 | G42: =EOMONTH(F42,1) -> 45808 | H42: =EOMONTH(G42,1) -> 45838 | I42: =EOMONTH(H42,1) -> 45869 | J42: =EOMONTH(I42,1) -> 45900 | ... BJ42: =EOMONTH(BI42,1) -> 47483
A43: OG | B43: ='Efs OG'!CS87 -> 0.022206958 | C43: ='Efs OG'!CT87 -> -0.0044084217 | D43: ='Efs OG'!CU87 -> 0.00095752086 | E43: ='Efs OG'!CV87 -> 0.0081371964 | F43: ='Efs OG'!CW87 -> 0.036637043 | G43: ='Efs OG'!CX87 -> 0.053373452 | H43: ='Efs OG'!CY87 -> 0.06690704 | I43: ='Efs OG'!CZ87 -> 0.067598391 | ... BJ43: ='Efs OG'!FA87 -> 0.026149662
A44: RL | B44: ='Efs Real'!L62 -> -0.25730637 | D44: ='Efs Real'!N62 -> -0.25698136 | E44: ='Efs Real'!O62 -> -0.23983151 | F44: ='Efs Real'!P62 -> -0.19809747 | G44: ='Efs Real'!Q62 -> -0.19683796 | H44: ='Efs Real'!R62 -> -0.17527368 | I44: ='Efs Real'!S62 -> -0.14711211 | J44: ='Efs Real'!T62 -> -0.11570119 | K44: ='Efs Real'!U62 -> -0.10873788 | ... P44: ='Efs Real'!Z62 -> -0.013552794
A45: MIN | B45: -0.02 | C45: -0.02 | D45: -0.02 | E45: -0.02 | F45: -0.02 | G45: -0.02 | H45: -0.02 | I45: -0.02 | J45: 0 | K45: 0 | L45: 0 | M45: 0 | N45: 0 | O45: 0 | P45: 0 | Q45: 0 | R45: 0 | S45: 0 | T45: 0 | U45: 0 | V45: 0 | W45: 0 | X45: 0 | Y45: 0 | Z45: 0 | AA45: 0 | AB45: 0 | AC45: 0 | AD45: 0 | AE45: 0 | AF45: 0 | AG45: 0 | AH45: 0 | AI45: 0 | AJ45: 0 | AK45: 0 | AL45: 0 | AM45: 0 | AN45: 0 | AO45: 0 | AP45: 0 | AQ45: 0 | AR45: 0 | AS45: 0 | AT45: 0 | AU45: 0 | AV45: 0 | AW45: 0 | AX45: 0 | AY45: 0 | AZ45: 0 | BA45: 0 | BB45: 0 | BC45: 0 | BD45: 0 | BE45: 0 | BF45: 0 | BG45: 0 | BH45: 0 | BI45: 0 | BJ45: 0
B48: 45657 | C48: =EOMONTH(B48,1) -> 45688 | D48: =EOMONTH(C48,1) -> 45716 | E48: =EOMONTH(D48,1) -> 45747 | F48: =EOMONTH(E48,1) -> 45777 | G48: =EOMONTH(F48,1) -> 45808 | H48: =EOMONTH(G48,1) -> 45838 | I48: =EOMONTH(H48,1) -> 45869 | J48: =EOMONTH(I48,1) -> 45900 | ... BJ48: =EOMONTH(BI48,1) -> 47483
A49: Aforo mínimo | B49: =IF(B4>7.5%, 1.5, 1.35) -> 1.35 | C49: =IF(C4>7.5%, 1.5, 1.35) -> 1.35 | D49: =IF(D4>7.5%, 1.5, 1.35) -> 1.35 | E49: =IF(E4>7.5%, 1.5, 1.35) -> 1.35 | F49: =IF(F4>7.5%, 1.5, 1.35) -> 1.35 | G49: =IF(G4>7.5%, 1.5, 1.35) -> 1.35 | H49: =IF(H4>7.5%, 1.5, 1.35) -> 1.35 | I49: =IF(I4>7.5%, 1.5, 1.35) -> 1.5 | J49: =IF(J4>7.5%, 1.5, 1.35) -> 1.5 | K49: =IF(J4>7.5%, 1.5, 1.35) -> 1.5 | L49: =IF(L4>7.5%, 1.5, 1.35) -> 1.5 | M49: =IF(M4>7.5%, 1.5, 1.35) -> 1.5 | N49: =IF(N4>7.5%, 1.5, 1.35) -> 1.5 | O49: =IF(O4>7.5%, 1.5, 1.35) -> 1.35 | P49: =IF(P4>7.5%, 1.5, 1.35) -> 1.35 | Q49: =IF(Q4>7.5%, 1.5, 1.35) -> 1.35 | R49: =IF(R4>7.5%, 1.5, 1.35) -> 1.35 | S49: =IF(S4>7.5%, 1.5, 1.35) -> 1.35 | ... BJ49: =IF(BJ4>7.5%, 1.5, 1.35) -> 1.35
A50: Saldo Insoluto | F50: 30000000 | H50: 43000000 | I50: 46000000 | J50: 52000000 | K50: 52000000
...

Sheet Efs Real
A1: Estado de resultados | B1: 44713 | C1: 44805 | D1: 44896 | E1: 44986 | F1: 45078 | G1: 45170 | H1: 45261 | I1: 45352 | J1: 45444 | K1: 45536 | L1: 45627 | M1: 45658 | N1: 45689 | O1: 45717 | P1: 45748 | Q1: 45778 | R1: 45809 | S1: 45839 | T1: 45870 | U1: 45901 | V1: 45931 | W1: 45962 | X1: 45992 | Y1: 46023 | Z1: 46054 | AA1: feb-26 restado
A2: Comisiones cobradas | B2: 3031000 | C2: 5147000 | D2: 7230000 | E2: 2199000 | F2: 2974000 | G2: 4870000 | H2: 7076000 | I2: 2519000 | J2: 5696000 | K2: 8874000 | L2: 12252000 | M2: 998000 | N2: =1957000-M2 -> 959000 | O2: =3385000-SUM(M2:N2) -> 1428000 | P2: 1908286 | Q2: 1343719.5 | R2: =8202000-SUM($M2:Q2) -> 1564994.5 | S2: 1214533.8 | T2: 1552749 | U2: =12705000-SUM($M2:T2) -> 1735717.2 | V2: 2341515.2 | W2: 1066373.4 | X2: 1580714.3 | Y2: 1053000 | Z2: 2144000 | AA2: =Z2-Y2 -> 1091000
A3: Comisiones pagadas | B3: -112000 | C3: -247000 | D3: -322000 | E3: -111000 | F3: -194000 | G3: -346000 | H3: -515000 | I3: -612000 | J3: -1574000 | K3: -2635000 | L3: -3675000 | M3: -415000 | N3: =-725000-M3 -> -310000 | O3: =-1056000-SUM(M3:N3) -> -331000 | P3: -195731 | Q3: -254716.28 | R3: =-1627000-SUM(M3:Q3) -> -120552.72 | S3: -245747.17 | T3: -109983.18 | U3: =-(SUM($M3:T3)+2407000) -> -424269.65 | V3: -239566.18 | W3: -96599.85 | X3: -181499.01 | Y3: -208000 | Z3: -388000 | AA3: =Z3-Y3 -> -180000
A4: Pagadas vs Cobradas | B4: =-B3/B2 -> 0.036951501 | C4: =-C3/C2 -> 0.04798912 | D4: =-D3/D2 -> 0.044536653 | E4: =-E3/E2 -> 0.05047749 | F4: =-F3/F2 -> 0.065232011 | G4: =-G3/G2 -> 0.071047228 | H4: =-H3/H2 -> 0.072781232 | I4: =-I3/I2 -> 0.24295355 | ... Z4: =-Z3/Z2 -> 0.18097015 | AA4: =Z4-Y4 -> -0.016560715
A5: Resultado por Servicios | B5: 2919000 | C5: 4900000 | D5: 6908000 | E5: 2088000 | F5: 2780000 | G5: 4524000 | H5: 6561000 | I5: 1907000 | J5: 4122000 | K5: =SUM(K2:K3) -> 6239000 | L5: =SUM(L2:L3) -> 8577000 | M5: =SUM(M2:M3) -> 583000 | N5: =SUM(N2:N3) -> 649000 | O5: =SUM(O2:O3) -> 1097000 | P5: =SUM(P2:P3) -> 1712555 | Q5: =SUM(Q2:Q3) -> 1089003.2 | R5: =SUM(R2:R3) -> 1444441.8 | ... Z5: =SUM(Z2:Z3) -> 1756000 | AA5: =Z5-Y5 -> 911000
A6: Ingresos por intereses | B6: 357000 | C6: 656000 | D6: 880000 | E6: 262000 | F6: 699000 | G6: 874000 | H6: 1256000 | I6: 386000 | J6: 761000 | K6: 1093000 | L6: 1569000 | M6: 286000 | N6: =731000-M6 -> 445000 | O6: =1121000-SUM(M6:N6) -> 390000 | P6: 566720 | Q6: 733525.58 | R6: =3124000-SUM(M6:Q6) -> 702754.42 | S6: 806638.8 | T6: 855943.36 | U6: =5540000-SUM($M6:T6) -> 753417.84 | V6: 1288378.6 | W6: 865868.25 | X6: 1031707.3 | Y6: 713000 | Z6: 1437000 | AA6: =Z6-Y6 -> 724000
A7: Resultado por valuación a valor razonable | B7: 1000 | C7: 231000 | D7: 263000 | E7: 19000 | F7: 538000 | G7: 1252000 | H7: 1282000 | I7: 1000 | J7: 1000 | K7: 1000 | L7: 1000 | M7: 0 | N7: =0-M7 -> 0 | O7: 0 | P7: 0 | Q7: -724598.78 | R7: =-1706000-SUM(M7:Q7) -> -981401.22 | S7: 0 | T7: -990373.36 | U7: =SUM($M7:T7)+2696000 -> -373.36 | V7: 0 | W7: -476229.42 | X7: 0 | Y7: 0 | Z7: 0 | AA7: =Z7-Y7 -> 0
A8: Gastos por Intereses | B8: -144000 | C8: -245000 | D8: -245000 | E8: 0 | F8: 0 | G8: 0 | H8: 0 | I8: 0 | J8: 0 | K8: 0 | L8: -238000 | M8: 0 | N8: =-188000-M8 -> -188000 | O8: =-305000-SUM(M8:N8) -> -117000 | P8: 0 | Q8: -898013.89 | R8: =-1867000-SUM(M8:Q8) -> -663986.11 | S8: -844486.11 | T8: -917944.44 | U8: =-(SUM($M8:T8)+4517000) -> -887569.45 | V8: -917944.45 | W8: -858722.21 | X8: -962823.51 | Y8: -943000 | Z8: -1779000 | AA8: =Z8-Y8 -> -836000
A9: Margen Financiero por Intermediación | B9: 3133000 | C9: 5542000 | D9: 7806000 | E9: 2369000 | F9: 4017000 | G9: 6650000 | H9: 9099000 | I9: 2294000 | J9: 4884000 | K9: 7333000 | L9: =SUM(L6:L8)+L5 -> 9909000 | M9: =SUM(M6:M8)+M5 -> 869000 | N9: =SUM(N6:N8)+N5 -> 906000 | O9: =SUM(O6:O8)+O5 -> 1370000 | P9: =SUM(P6:P8)+P5 -> 2279275 | Q9: =SUM(Q6:Q8)+Q5 -> 199916.1 | R9: =R5+SUM(R6:R8) -> 501808.9 | S9: =S5+SUM(S6:S8) -> 930939.31 | T9: =T5+SUM(T6:T8) -> 390391.41 | U9: =U5+SUM(U6:U8) -> 1176922.6 | V9: =V5+SUM(V6:V8) -> 2472383.1 | W9: =W5+SUM(W6:W8) -> 500690.15 | X9: =X5+SUM(X6:X8) -> 1468099 | Y9: =Y5+SUM(Y6:Y8) -> 615000 | Z9: =Z5+Z6+Z8 -> 1414000 | AA9: =Z9-Y9 -> 799000
A10: Otros ingresos (egresos) de la operación | B10: 1886000 | C10: 1882000 | D10: 1597000 | E10: -401000 | F10: -512000 | G10: -565000 | H10: -602000 | I10: 67000 | J10: 65000 | K10: 171000 | L10: 144000 | M10: -4000 | N10: =-47000-M10 -> -43000 | O10: =-91000-SUM(M10:N10) -> -44000 | P10: -27793 | Q10: -155119.55 | R10: =-444000-SUM(M10:Q10) -> -170087.45 | S10: -159333.15 | T10: -258050.5 | U10: =-(SUM($M10:T10)+1098000) -> -236616.35 | V10: -462793.95 | W10: -466796.14 | X10: -156531.81 | Y10: -38000 | Z10: -84000 | AA10: =Z10-Y10 -> -46000
A11: Gastos de Administración y Promoción | B11: -4616000 | C11: -7689000 | D11: -13731000 | E11: -3446000 | F11: -7176000 | G11: -11329000 | H11: -15660000 | I11: -4272000 | J11: -8109000 | K11: -12211000 | L11: -16138000 | M11: -1622000 | N11: =-2677000-M11 -> -1055000 | O11: =-4358000-SUM(M11:N11) -> -1681000 | P11: -1590408 | Q11: -1955019.4 | R11: =-9500000-SUM(M11:Q11) -> -1596572.6 | S11: -1598596.9 | T11: -1622859 | U11: =-(SUM($M11:T11)+13964000) -> -1242544 | V11: -1908771.3 | W11: -1615578.5 | X11: -1791374.2 | Y11: -2031000 | Z11: -3703000 | AA11: =Z11-Y11 -> -1672000
A12: Impuestos a la utilidad y diferido | B12: 434000 | C12: 378000 | D12: 449000 | E12: 0 | F12: -154000 | G12: -174000 | H12: -332000 | I12: 0 | J12: 0 | K12: 0 | L12: 0 | M12: 0 | N12: =0-M12 -> 0 | O12: 0 | P12: 0 | Q12: 0 | R12: =0-SUM(M12:Q12) -> 0 | S12: =0-SUM(N12:R12) -> 0 | T12: =0-SUM(O12:S12) -> 0 | U12: =SUM($M12:T12)+0 -> 0 | V12: 0 | Y12: 0 | Z12: 0 | AA12: =Z12-Y12 -> 0
A13: Resultado Neto | B13: 837000 | C13: 113000 | D13: -3879000 | E13: -1478000 | F13: -3825000 | G13: -5418000 | H13: -7495000 | I13: -1911000 | J13: -3160000 | K13: -4707000 | L13: =SUM(L10:L12)+L9 -> -6085000 | M13: =SUM(M10:M12)+M9 -> -757000 | N13: =SUM(N10:N12)+N9 -> -192000 | O13: =SUM(O10:O12)+O9 -> -355000 | P13: =SUM(P10:P12)+P9 -> 661074 | Q13: =SUM(Q10:Q12)+Q9 -> -1910222.9 | R13: =SUM(R10:R12)+R9 -> -1264851.1 | S13: =SUM(S10:S12)+S9 -> -826990.79 | ... Y13: =SUM(Y10:Y12)+Y9 -> -1454000 | Z13: =Z9+Z10+Z11 -> -2373000 | AA13: =Z13-Y13 -> -919000
B14: 6 | C14: 9 | D14: 12 | E14: 3 | F14: 6 | G14: 9 | H14: 12 | I14: 3 | J14: 6 | K14: 9 | L14: 12 | M14: 1 | N14: 2 | V14: | | W14: | | X14: | | Y14: |
A15: Cuentas Bajo Administración | B15: 44713 | C15: 44805 | D15: 44896 | E15: 44986 | F15: 45078 | G15: 45170 | H15: 45261 | I15: 45352 | J15: 45444 | K15: 45536 | L15: 45627 | M15: 45658 | N15: 45689 | O15: 45717 | P15: 45748 | Q15: 45778 | R15: 45809 | S15: 45839 | T15: 45870 | U15: 45901 | V15: 45931 | W15: 45931 | X15: 45992 | Y15: 46023 | Z15: 46054
A16: Deuda cuentas corrientes | B16: 2339000 | C16: 3307000 | D16: 5406000 | E16: 4330000 | F16: 4512000 | G16: 4995000 | H16: 6718000 | I16: 5575000 | J16: 5215000 | K16: 6889000 | L16: 11052000 | M16: 10315000 | N16: 10349000 | O16: 10201000 | P16: 6418014 | R16: 3424000 | U16: 4130000 | Y16: 5222000 | Z16: 7042000
A17: Depósitos de inversionistas | B17: 4458000 | C17: 5356000 | D17: 4906000 | E17: 7587000 | F17: 7267000 | G17: 6142000 | H17: 6825000 | I17: 8451000 | J17: 9034000 | K17: 8643000 | L17: 7734000 | M17: 7538000 | N17: 7236000 | O17: 7543000 | P17: 10336837 | R17: 11544000 | U17: 7770000 | Y17: 7943000 | Z17: 10938000
A18: Otras cuentas corrientes | B18: 6524000 | C18: 8079000 | D18: 10063000 | E18: 11779000 | F18: 11608000 | G18: 10980000 | H18: 13791000 | I18: 13851000 | J18: 13566000 | K18: 15240000 | L18: 17276000 | M18: 13842000 | N18: 17655000 | O18: 18747000 | P18: 17709968 | R18: 0 | U18: 12210000 | Y18: 13241000 | Z18: 17906000
A19: Instrumentos financieros de clientes en administración | B19: 97373000 | C19: 100058000 | D19: 111072000 | E19: 116535000 | F19: 119344000 | G19: 130759000 | H19: 136571000 | I19: 152097000 | J19: 152920000 | K19: 160492000 | L19: 173957000 | M19: 175565000 | N19: 173917000 | O19: 184923000 | P19: 194537486 | R19: 202657000 | U19: 204013000 | Y19: 196293000 | Z19: 196245000
A20: Comisiones vs. Cartera | B20: =(B2/B14*12)/B19 -> 0.062255451 | C20: =(C2/C14*12)/C19 -> 0.068586886 | D20: =(D2/D14*12)/D19 -> 0.065092913 | E20: =(E2/E14*12)/E19 -> 0.07547947 | F20: =(F2/F14*12)/F19 -> 0.049839121 | G20: =(G2/G14*12)/G19 -> 0.049658787 | H20: =(H2/H14*12)/H19 -> 0.051811878 | I20: =(I2/I14*12)/I19 -> 0.066247198 | ... L20: =(L2/L14*12)/L19 -> 0.070431199 | M20: =(M2*12)/M19 -> 0.068214052 | N20: =(N2*12)/N19 -> 0.066169495 | O20: =(O2*12)/O19 -> 0.092665596 | P20: =(P2*12)/P19 -> 0.11771218 | Q20: =(Q2*12)/Q19 -> #DIV/0! | R20: =(R2*12)/R19 -> 0.09266857 | U20: =(U2*12)/U19 -> 0.1020945 | V20: =(V2*12)/V19 -> #DIV/0! | W20: =(W2*12)/W19 -> #DIV/0! | X20: =(X2*12)/X19 -> #DIV/0! | Y20: =(Y2*12)/Y19 -> 0.064373156 | Z20: =(Z2*12)/Z19 -> 0.13110143
A21: Colaterales recibidos en garanía por cuenta de solicitantes | B21: 117285000 | C21: 125400000 | D21: 134270000 | E21: 151502000 | F21: 166160000 | G21: 186115000 | H21: 203482000 | I21: 198647000 | J21: 208366000 | K21: 216152000 | L21: 231653000 | M21: 233750000 | N21: 242718000 | O21: 247111000 | P21: 253062289 | R21: 271081000 | U21: 270589000 | Y21: 252127000 | Z21: 252751000
A22: Total Operaciones de Administración | B22: 227979000 | C22: 242200000 | D22: 265717000 | E22: 291733000 | F22: 308891000 | G22: 338991000 | H22: 367387000 | I22: 378621000 | J22: 389101000 | K22: 407416000 | L22: =L21+L19+L18+L17+L16 -> 441672000 | M22: =M21+M19+M18+M17+M16 -> 441010000 | N22: =N21+N19+N18+N17+N16 -> 451875000 | O22: =O21+O19+O18+O17+O16 -> 468525000 | P22: =P21+P19+P18+P17+P16 -> 482064594 | Q22: =Q21+Q19+Q18+Q17+Q16 -> 0 | R22: =R21+R19+R18+R17+R16 -> 488706000 | U22: =U21+U19+U18+U17+U16 -> 498712000 | V22: =V21+V19+V18+V17+V16 -> 0 | W22: =W21+W19+W18+W17+W16 -> 0 | X22: =X21+X19+X18+X17+X16 -> 0 | Y22: =Y21+Y19+Y18+Y17+Y16 -> 474826000 | Z22: =Z21+Z19+Z18+Z17+Z16 -> 484882000
M23: 1 | N23: 2
A24: Balance General | B24: 44713 | C24: 44805 | D24: 44896 | E24: 44986 | F24: 45078 | G24: 45170 | H24: 45261 | I24: 45352 | J24: 45444 | K24: 45536 | L24: 45627 | M24: 45658 | N24: 45689 | O24: 45717 | P24: 45748 | Q24: 45778 | R24: 45809 | S24: 45839 | T24: 45870 | U24: 45901 | V24: 45931 | W24: 45931 | X24: 45992 | Y24: 46023 | Z24: 46054
A25: Efectivo y equivalentes de efectivo | B25: 544000 | C25: 6371000 | D25: 1962000 | E25: 3241000 | F25: 2397000 | G25: 3151000 | H25: 945000 | I25: 113000 | J25: 634000 | K25: 458000 | L25: 334000 | M25: 678000 | N25: 65000 | O25: 443000 | P25: 279981 | Q25: 1501430.3 | R25: 253000 | S25: 661157.8 | T25: 62726.5 | U25: 121000 | V25: 401123.31 | W25: 687768.41 | X25: 290091.8 | Y25: 160000 | Z25: 813000
A26: Inversiones en instrumentos financieros (cartera RG) | B26: 6209000 | C26: 6678000 | D26: 6905000 | E26: 6430000 | F26: 6187000 | G26: 1298000 | H26: 1996000 | I26: 1476000 | J26: 1516000 | K26: 6208000 | L26: 25517000 | M26: 24388000 | N26: 24356000 | O26: 38503000 | P26: 50875285 | Q26: 50875230 | R26: 61878000 | S26: 72564877 | T26: 72334955 | U26: 69199000 | V26: 77800817 | W26: 72500790 | X26: 64999893 | Y26: 63365000 | Z26: 61408000
A27: Estimación de pérdidas crediticias | B27: -1683000 | C27: -1495000 | D27: -1548000 | E27: -1550000 | F27: -1221000 | G27: -403000 | H27: -403000 | I27: -403000 | J27: -403000 | K27: -403000 | L27: -403000 | M27: -403000 | N27: -403000 | O27: -2503000 | P27: -2503265 | Q27: -3227863.7 | R27: -4209000 | S27: -4209174.6 | T27: -5199548 | U27: -5200000 | V27: -5199548 | W27: -5675777.4 | X27: -5675777.4 | Y27: -5676000 | Z27: -5676000
A28: Cuentas por cobrar, neto | B28: 325000 | C28: 1231000 | D28: 6980000 | E28: 7253000 | F28: 7160000 | G28: 11824000 | H28: 11779000 | I28: 11677000 | J28: 11821000 | K28: 11405000 | L28: 11266000 | M28: 11398000 | N28: 13552000 | O28: 12011000 | P28: 12321419 | Q28: 12473029 | R28: 11183000 | S28: 11623339 | T28: 12428384 | U28: 13152000 | V28: 13035761 | W28: 11717400 | X28: 12311004 | Y28: 12186000 | Z28: 12264000
A29: Pagos anticipados y otros activos, neto | B29: 1630000 | C29: 2000000 | D29: 2472000 | E29: 1696000 | F29: 1675000 | G29: 1529000 | H29: 1549000 | I29: 1511000 | J29: 1460000 | K29: 1419000 | L29: 1382000 | M29: 1617000 | N29: 1450000 | O29: 2747000 | P29: 4619536 | Q29: =2271537.47+3494711.12+1037057.22 -> 6803305.8 | R29: 7792000 | S29: 4781463.7 | T29: 5390587.6 | U29: 6322000 | V29: 7862889 | W29: 7908494.4 | X29: 10047810 | Y29: 11203000 | Z29: 12406000
A30: Propiedades, mobiliario y equipo, neto | B30: 132000 | C30: 114000 | D30: 96000 | E30: 109000 | F30: 180000 | G30: 174000 | H30: 207000 | I30: 208000 | J30: 210000 | K30: 208000 | L30: 238000 | M30: 235000 | N30: 232000 | O30: 243000 | P30: 242599 | Q30: 642052.93 | R30: 300000 | S30: 656383.1 | T30: 656383.1 | U30: 301000 | V30: 684494.31 | W30: 684494.31 | X30: 684494.31 | Y30: 452000 | Z30: 394000
A31: Depreciación acumulada | Q31: -354157.06 | R31: 0 | S31: -354947.44 | T31: -355342.63 | U31: 0 | V31: -356133.01 | W31: -356528.2 | X31: -356923.39 | Y31: 0
A32: Activo por impuestos a la utilidad diferidos, neto | B32: 505000 | C32: 449000 | D32: 520000 | E32: 521000 | F32: 366000 | G32: 346000 | H32: 268000 | I32: 346000 | J32: 346000 | K32: 346000 | L32: 346000 | M32: 346000 | N32: 346000 | O32: 1082000 | P32: 1082189 | Q32: 1082189.3 | R32: 1082000 | S32: 1082189.3 | T32: 1082189.3 | U32: 1082000 | V32: 1082189.3 | W32: 1082189.3 | X32: 1082189.3 | Y32: 1361000 | Z32: 1669000
A33: Total Activo | B33: =SUM(B25:B32) -> 7662000 | C33: =SUM(C25:C32) -> 15348000 | D33: =SUM(D25:D32) -> 17387000 | E33: =SUM(E25:E32) -> 17700000 | F33: =SUM(F25:F32) -> 16744000 | G33: =SUM(G25:G32) -> 17919000 | H33: =SUM(H25:H32) -> 16341000 | I33: =SUM(I25:I32) -> 14928000 | ... Z33: =SUM(Z25:Z32) -> 83278000
A35: Préstamos de corto plazo | B35: 1058000 | C35: 115000 | D35: 17000 | E35: 50000 | F35: 89000 | G35: 142000 | H35: 114000 | I35: 255000 | J35: 59000 | K35: 139000 | L35: 60000 | M35: 75000 | N35: 358000 | O35: 0 | P35: 86288 | Q35: 164643.18 | R35: 81000 | S35: 119104.48 | T35: 101245.29 | U35: 374000 | V35: 178760.11 | W35: 72353.39 | X35: 66838.97 | Y35: 378000 | Z35: 94000
A36: Préstamos de largo plazo | B36: 1477000 | C36: 10611000 | D36: 10405000 | E36: 9400000 | F36: 8803000 | G36: 8206000 | H36: 7609000 | I36: 7459000 | J36: 6862000 | K36: 11265000 | L36: 10465000 | M36: 10334000 | N36: 10465000 | O36: 24549000 | P36: 34468353 | Q36: 38468353 | R36: 47070000 | S36: 55574615 | T36: =55574614.97 -> 55574615 | U36: 55327000 | V36: 64675005 | W36: 59840978 | X36: 54586440 | Y36: 54268000 | Z36: 54268000
A37: Contribuciones por pagar | B37: 95000 | C37: 155000 | D37: 497000 | E37: 450000 | F37: 316000 | G37: 461000 | H37: 348000 | I37: 633000 | J37: 1021000 | K37: 1011000 | L37: 1552000 | M37: 1563000 | N37: 2074000 | O37: 2501000 | P37: 3168518 | Q37: 3433525.3 | R37: 2454000 | S37: 2876758.8 | T37: 3492117.8 | U37: 3121000 | V37: 3759750 | W37: 3441035.4 | X37: =4483008.93-X38 -> 4250057.4 | Y37: 4668000 | Z37: 5417000
A38: Acreedores diversas y otras cuentas por pagar | B38: 185000 | C38: 310000 | D38: 335000 | E38: 505000 | F38: 41000 | G38: 229000 | H38: 356000 | I38: 80000 | J38: 62000 | K38: 223000 | L38: 31000 | M38: 398000 | N38: 585000 | O38: 600000 | P38: 645113 | Q38: 669184.7 | R38: 296000 | S38: 352413.85 | T38: 463869.94 | U38: 501000 | V38: 582334.27 | W38: 673578.63 | X38: 232951.49 | Y38: 398000 | Z38: 508000
A39: Aportaciones para futuros aumentos de capital como pasivos | B39: 0 | C39: 0 | D39: 0 | E39: 0 | F39: 0 | G39: 0 | H39: 0 | I39: 0 | J39: 2250000 | K39: 0 | L39: 0 | M39: 0 | N39: 0 | O39: 0 | R39: 0 | S39: 0 | T39: 0 | U39: 0 | V39: 0 | W39: 0 | X39: 0 | Y39: 0
A40: Pasivo por impuestos a la utilidad | B40: 44000 | C40: 120000 | D40: 88000 | E40: 44000 | F40: 92000 | G40: 71000 | H40: 164000 | I40: 270000 | J40: 211000 | K40: 294000 | L40: 1094000 | M40: 1114000 | N40: 1485000 | O40: 1900000 | P40: 2355861 | Q40: 2720411.4 | R40: 2744000 | S40: 3021912.8 | T40: 3340183.9 | U40: 3268000 | V40: 3726144.4 | W40: 3808299.5 | X40: 4221362 | Y40: 4732000 | Z40: 5272000
A41: Pasivo por Beneficios a Empleados | B41: 0 | C41: 0 | D41: 0 | E41: 185000 | F41: 185000 | G41: 185000 | H41: 0 | I41: 232000 | J41: 368000 | K41: 506000 | L41: 653000 | M41: 707000 | N41: 755000 | O41: 1185000 | P41: 1038792 | Q41: 1094502.7 | R41: 1152000 | S41: 1207415.1 | T41: 1265752.7 | U41: 1158000 | V41: 1060969.9 | W41: 965640.63 | X41: 757993.75 | Y41: 792000 | Z41: 826000
...

Sheet Efs OG
B1: 42736 | C1: 42767 | D1: 42795 | E1: 42826 | F1: 42856 | G1: 42887 | H1: 42917 | I1: 42948 | J1: 42979 | K1: 43009 | L1: 43040 | M1: 43070 | N1: 43101 | O1: 43132 | P1: 43160 | Q1: 43191 | R1: 43221 | S1: 43252 | T1: 43282 | U1: 43313 | V1: 43344 | W1: 43374 | X1: 43405 | Y1: 43435 | Z1: 43466 | AA1: 43497 | AB1: 43525 | AC1: 43556 | AD1: 43586 | AE1: 43617 | AF1: 43647 | AG1: 43678 | AH1: 43709 | AI1: 43739 | AJ1: 43770 | AK1: 43800 | AL1: 43831 | AM1: 43862 | AN1: 43891 | AO1: 43922 | AP1: 43952 | AQ1: 43983 | AR1: 44013 | AS1: 44044 | AT1: 44075 | AU1: 44105 | AV1: 44136 | AW1: 44166 | AX1: 44197 | AY1: 44228 | AZ1: 44256 | BA1: 44287 | BB1: 44317 | BC1: 44348 | BD1: 44378 | BE1: 44409 | BF1: 44440 | BG1: 44470 | BH1: 44501 | BI1: 44531 | BJ1: 44562 | BK1: 44593 | BL1: 44621 | BM1: 44652 | BN1: 44682 | BO1: 44713 | BP1: 44743 | BQ1: 44774 | BR1: 44805 | BS1: 44835 | BT1: 44866 | BU1: 44896 | BV1: 44927 | BW1: 44958 | BX1: 44986 | BY1: 45017 | BZ1: 45047 | CA1: 45078 | CB1: 45108 | CC1: 45139 | CD1: 45170 | CE1: 45200 | CF1: 45231 | CG1: 45261 | CH1: 45292 | CI1: 45323 | CJ1: 45352 | CK1: 45383 | CL1: 45413 | CM1: 45444 | CN1: 45474 | CO1: 45505 | CP1: 45536 | CQ1: 45566 | CR1: 45597 | CS1: 45627 | CT1: 45658 | CU1: 45689 | CV1: 45717 | CW1: 45748 | CX1: 45778 | CY1: 45809 | CZ1: 45839 | DA1: 45870 | DB1: 45901 | DC1: 45931 | DD1: 45962 | DE1: 45992 | DF1: 46023 | DG1: 46054 | DH1: 46082 | DI1: 46113 | DJ1: 46143 | DK1: 46174 | DL1: 46204 | DM1: 46235 | DN1: 46266 | DO1: 46296 | DP1: 46327 | DQ1: 46357 | DR1: 46388 | DS1: 46419 | DT1: 46447 | DU1: 46478 | DV1: 46508 | DW1: 46539 | DX1: 46569 | DY1: 46600 | DZ1: 46631 | EA1: 46661 | EB1: 46692 | EC1: 46722 | ED1: 46753 | EE1: 46784 | EF1: 46813 | EG1: 46844 | EH1: 46874 | EI1: 46905 | EJ1: 46935 | EK1: 46966 | EL1: 46997 | EM1: 47027 | EN1: 47058 | EO1: 47088 | EP1: 47119 | EQ1: 47150 | ER1: 47178 | ES1: 47209 | ET1: 47239 | EU1: 47270 | EV1: 47300 | EW1: 47331 | EX1: 47362 | EY1: 47392 | EZ1: 47423 | FA1: 47453
A2: Ingresos por Intereses | B2: =B52*B46/12 -> #REF! | C2: =C52*C46/12 -> #REF! | D2: =D52*D46/12 -> #REF! | E2: =E52*E46/12 -> #REF! | F2: =F52*F46/12 -> #REF! | G2: =G52*G46/12 -> #REF! | H2: =H52*H46/12 -> #REF! | I2: =I52*I46/12 -> #REF! | ... CG2: =CG52*CG46/12 -> #REF! | CH2: 17680.753 | CI2: 17631.547 | CJ2: 17771.454 | CK2: 17390.616 | CL2: 17744.96 | CM2: 18224.778 | CN2: 18220.482 | CO2: 18457.067 | CP2: 92383.189 | CQ2: 97493.857 | CR2: 370452.24 | CS2: 370104.55 | CT2: 369788.25 | CU2: 653527.02 | CV2: 867596.47 | CW2: 1365097.5 | CX2: 1577717.7 | CY2: 1794483.5 | CZ2: 1797754.2 | DA2: 1802069.4 | DB2: 1800032.5 | DC2: 1803977.5 | DD2: 1808662.7 | DE2: 1813038.6 | DF2: 1815206.1 | DG2: 1820111.5 | DH2: 1824580 | DI2: 1831553.4 | DJ2: 1833679.1 | DK2: 1838117.9 | DL2: 1840940.3 | DM2: 1843972.6 | DN2: 1841067.7 | DO2: 1839090.3 | DP2: 1842276.6 | DQ2: 1845919 | DR2: 1852898 | DS2: 1855184.6 | DT2: 1859231.2 | DU2: 1858152.4 | DV2: 1856673.3 | DW2: 1861887.4 | DX2: 1865080.1 | DY2: 1869191.8 | DZ2: 1877368.9 | EA2: 1887346.9 | EB2: 1897349.1 | EC2: 1910809.5 | ED2: 1922911 | EE2: 1942155.9 | EF2: 1957542.7 | EG2: 1964199.1 | EH2: 1985114.5 | EI2: 2015466.6 | EJ2: 2028301 | EK2: 2022878.3 | EL2: 2051451.8 | EM2: 2068222.2 | EN2: 2101442.8 | EO2: 2078548.2 | EP2: 2118380.9 | EQ2: 2104254.2 | ER2: 2166687.6 | ES2: 2240644.2 | ET2: 2358818.6 | EU2: 2437515.7 | EV2: 2888535.2 | EW2: 3092187.3 | EX2: 3309111.6 | EY2: 0 | EZ2: 0 | FA2: 0
A4: Comisiones de Apertura y Preoriginación | B4: =#REF! -> #REF! | C4: =#REF! -> #REF! | D4: =#REF! -> #REF! | E4: =#REF! -> #REF! | F4: =#REF! -> #REF! | G4: =#REF! -> #REF! | H4: =#REF! -> #REF! | I4: =#REF! -> #REF! | ... CG4: =#REF! -> #REF! | CH4: 143476.08 | CI4: 112522.68 | CJ4: 41129.2 | CK4: 153075.28 | CL4: 176065.56 | CM4: 103720.42 | CN4: 121839.7 | CO4: 167684.58 | CP4: 157378.68 | CQ4: 17664.24 | CR4: 512465.9 | CS4: 509675.44 | CT4: 107007.41 | CU4: 504751.89 | CV4: 404969.95 | CW4: 405732.01 | CX4: 102572.67 | CY4: 98017.185 | CZ4: 98115.729 | DA4: 98093.801 | DB4: 98918.412 | DC4: 93347.041 | DD4: 93095.718 | DE4: 93475.457 | DF4: 92957.612 | DG4: 90887.966 | DH4: 90800.018 | DI4: 89874.54 | DJ4: 90555.282 | DK4: 87312.689 | DL4: 85900.313 | DM4: 83512.655 | DN4: 81113.591 | DO4: 75895.662 | DP4: 71991.6 | DQ4: 70567.38 | DR4: 69730.996 | DS4: 70314.591 | DT4: 68753.719 | DU4: 67867.102 | DV4: 64951.381 | DW4: 62505.595 | DX4: 62190.12 | DY4: 61266.041 | DZ4: 60442.123 | EA4: 60346.06 | EB4: 60449.285 | EC4: 60189.681 | ED4: 60402.641 | EE4: 59852.449 | EF4: 60235.171 | EG4: 59438.062 | EH4: 57056.844 | EI4: 56289.404 | EJ4: 55829.9 | EK4: 53338.117 | EL4: 49704.746 | EM4: 48560.516 | EN4: 46616.913 | EO4: 45445.52 | EP4: 42648.874 | EQ4: 41868.456 | ER4: 40099.298 | ES4: 39730.497 | ET4: 39156.57 | EU4: 38543.819 | EV4: 37456.97 | EW4: 37373.41 | EX4: 36008.875 | EY4: 35715.251 | EZ4: 35792.194 | FA4: 36060.635
A5: Comisiones de Administración | B5: =#REF! -> #REF! | C5: =#REF! -> #REF! | D5: =#REF! -> #REF! | E5: =#REF! -> #REF! | F5: =#REF! -> #REF! | G5: =#REF! -> #REF! | H5: =#REF! -> #REF! | I5: =#REF! -> #REF! | ... CG5: =#REF! -> #REF! | CH5: 619810.34 | CI5: 657343.22 | CJ5: 687399.6 | CK5: 685065.91 | CL5: 728561.52 | CM5: 786023.94 | CN5: 805613.79 | CO5: 839588.74 | CP5: 894218.17 | CQ5: 950629.83 | CR5: 1251720.6 | CS5: 1279712.2 | CT5: 1307559.7 | CU5: 1535597.7 | CV5: 1713039.1 | CW5: 2088174.3 | CX5: 2262214.9 | CY5: 2438594 | CZ5: 2464445.3 | DA5: 2489734.3 | DB5: 2511899.7 | DC5: 2536695.7 | DD5: 2560939.4 | DE5: 2584726.9 | DF5: 2606460.8 | DG5: 2628595.5 | DH5: 2649185.3 | DI5: 2670682.5 | DJ5: 2690285.6 | DK5: 2710977.4 | DL5: 2730208 | DM5: 2749958.2 | DN5: 2766892.8 | DO5: 2784344.4 | DP5: 2803323.9 | DQ5: 2821486.4 | DR5: 2839905.6 | DS5: 2857738.3 | DT5: 2875901.9 | DU5: 2891815.6 | DV5: 2908971.6 | DW5: 2925582.8 | DX5: 2941848.8 | DY5: 2958283.3 | DZ5: 2974665.3 | EA5: 2991134.6 | EB5: 3007849.2 | EC5: 3023829.6 | ED5: 3039436.8 | EE5: 3055347 | EF5: 3070113.2 | EG5: 3084229.3 | EH5: 3099258 | EI5: 3114557.6 | EJ5: 3128991.5 | EK5: 3143002.3 | EL5: 3158360.3 | EM5: 3173456.8 | EN5: 3189060.6 | EO5: 3204004.8 | EP5: 3220065.3 | EQ5: 3235774.9 | ER5: 3252299 | ES5: 3268852.2 | ET5: 3285516.7 | EU5: 3302082.6 | EV5: 3319270.8 | EW5: 3335967.7 | EX5: 3353323.6 | EY5: 3370993.5 | EZ5: 3388889.6 | FA5: 3406919.9
A6: Comisiones de Éxito | B6: =IF(B1>Supuestos!$D$22,Supuestos!$B$22*B41,Supuestos!$B$21*B44) -> #REF! | C6: =IF(C1>Supuestos!$D$22,Supuestos!$B$22*C41,Supuestos!$B$21*C44) -> #REF! | D6: =IF(D1>Supuestos!$D$22,Supuestos!$B$22*D41,Supuestos!$B$21*D44) -> #REF! | E6: =IF(E1>Supuestos!$D$22,Supuestos!$B$22*E41,Supuestos!$B$21*E44) -> #REF! | F6: =IF(F1>Supuestos!$D$22,Supuestos!$B$22*F41,Supuestos!$B$21*F44) -> #REF! | G6: =IF(G1>Supuestos!$D$22,Supuestos!$B$22*G41,Supuestos!$B$21*G44) -> #REF! | H6: =IF(H1>Supuestos!$D$22,Supuestos!$B$22*H41,Supuestos!$B$21*H44) -> #REF! | I6: =IF(I1>Supuestos!$D$22,Supuestos!$B$22*I41,Supuestos!$B$21*I44) -> #REF! | ... CG6: =IF(CG1>Supuestos!$D$22,Supuestos!$B$22*CG41,Supuestos!$B$21*CG44) -> #REF! | CH6: 124346.62 | CI6: 125886.47 | CJ6: 122884.67 | CK6: 122582.87 | CL6: 128007.74 | CM6: 129375.4 | CN6: 126787.78 | CO6: 125012.58 | CP6: 120596.59 | CQ6: 196094.06 | CR6: 199463.91 | CS6: 201416.1 | CT6: 203391.15 | CU6: 205627.27 | CV6: 207949.64 | CW6: 209926.23 | CX6: 211801.08 | CY6: 214183.93 | CZ6: 216562.55 | DA6: 219090.86 | DB6: 220865.75 | DC6: 223387.58 | DD6: 226026.39 | DE6: 228653.2 | DF6: 231024.64 | DG6: 233767.06 | DH6: 236480.59 | DI6: 239547.9 | DJ6: 242009.29 | DK6: 244797.5 | DL6: 247394.74 | DM6: 250041.99 | DN6: 251899.06 | DO6: 253889.01 | DP6: 256606.61 | DQ6: 259412.08 | DR6: 262716.34 | DS6: 265385.2 | DT6: 268330.03 | DU6: 270555.91 | DV6: 272735.12 | DW6: 275917.81 | DX6: 278829.8 | DY6: 281906.17 | DZ6: 285629.55 | EA6: 289669.79 | EB6: 293759.66 | EC6: 298435.64 | ED6: 302953.96 | EE6: 308659.88 | EF6: 313821.09 | EG6: 317632.79 | EH6: 323806.62 | EI6: 331612.11 | EJ6: 336617.45 | EK6: 338621.66 | EL6: 346366.95 | EM6: 352205.58 | EN6: 360938.22 | EO6: 360068.76 | EP6: 370109.65 | EQ6: 370783.2 | ER6: 385040.55 | ES6: 401575 | ET6: 426350.58 | EU6: 444317.28 | EV6: 530995.74 | EW6: 573248.14 | EX6: 618650.62 | EY6: 0 | EZ6: 0 | FA6: 0
A7: Total Comisiones | B7: =SUM(B4:B6) -> #REF! | C7: =SUM(C4:C6) -> #REF! | D7: =SUM(D4:D6) -> #REF! | E7: =SUM(E4:E6) -> #REF! | F7: =SUM(F4:F6) -> #REF! | G7: =SUM(G4:G6) -> #REF! | H7: =SUM(H4:H6) -> #REF! | I7: =SUM(I4:I6) -> #REF! | ... CQ7: =SUM(CQ4:CQ6) -> 1164388.1 | CR7: =SUM(CR4:CR6)*Supuestos!$B$4 -> 1767285.3 | CS7: =SUM(CS4:CS6)*Supuestos!$B$4 -> 1791723.4 | CT7: =SUM(CT4:CT6)*Supuestos!$B$4 -> 1456162.4 | CU7: =SUM(CU4:CU6)*Supuestos!$B$4 -> 2021379.1 | CV7: =SUM(CV4:CV6)*Supuestos!$B$4 -> 2093362.8 | CW7: =SUM(CW4:CW6)*Supuestos!$B$4 -> 2433449.3 | CX7: =SUM(CX4:CX6)*Supuestos!$B$4 -> 2318929.8 | CY7: =SUM(CY4:CY6)*Supuestos!$B$4 -> 2475715.6 | ... FA7: =SUM(FA4:FA6)*Supuestos!$B$4 -> 3098682.5
CR9: =#REF!+CR41*0.1 -> #REF! | CS9: =#REF!+CS41*0.1 -> #REF! | CT9: =#REF!+CT41*0.1 -> #REF! | CU9: =#REF!+CU41*0.1 -> #REF! | CV9: =#REF!+CV41*0.1 -> #REF! | CW9: =#REF!+CW41*0.1 -> #REF! | CX9: =#REF!+CX41*0.1 -> #REF! | CY9: =#REF!+CY41*0.1 -> #REF! | ... FA9: =#REF!+FA41*0.1 -> #REF!
CQ10: 0.205 | CR10: =CR9/POWER((1+($CQ$10/12)),CR11) -> #REF! | CS10: =CS9/POWER((1+($CQ$10/12)),CS11) -> #REF! | CT10: =CT9/POWER((1+($CQ$10/12)),CT11) -> #REF! | CU10: =CU9/POWER((1+($CQ$10/12)),CU11) -> #REF! | CV10: =CV9/POWER((1+($CQ$10/12)),CV11) -> #REF! | CW10: =CW9/POWER((1+($CQ$10/12)),CW11) -> #REF! | CX10: =CX9/POWER((1+($CQ$10/12)),CX11) -> #REF! | CY10: =CY9/POWER((1+($CQ$10/12)),CY11) -> #REF! | ... FA10: =FA9/POWER((1+($CQ$10/12)),FA11) -> #REF!
CR11: 0 | CS11: 1 | CT11: 2 | CU11: 3 | CV11: 4 | CW11: 5 | CX11: 6 | CY11: 7 | CZ11: 8 | DA11: 9 | DB11: 10 | DC11: 11 | DD11: 12 | DE11: 13 | DF11: 14 | DG11: 15 | DH11: 16 | DI11: 17 | DJ11: 18 | DK11: 19 | DL11: 20 | DM11: 21 | DN11: 22 | DO11: 23 | DP11: 24 | DQ11: 25 | DR11: 26 | DS11: 27 | DT11: 28 | DU11: 29 | DV11: 30 | DW11: 31 | DX11: 32 | DY11: 33 | DZ11: 34 | EA11: 35 | EB11: 36 | EC11: 37 | ED11: 38 | EE11: 39 | EF11: 40 | EG11: 41 | EH11: 42 | EI11: 43 | EJ11: 44 | EK11: 45 | EL11: 46 | EM11: 47 | EN11: 48 | EO11: 49 | EP11: 50 | EQ11: 51 | ER11: 52 | ES11: 53 | ET11: 54 | EU11: 55 | EV11: 56 | EW11: 57 | EX11: 58 | EY11: 59 | EZ11: 60 | FA11: 61
CR12: {=NPV(CQ10/12,CR9:EC9)} -> #REF! | CS12: =SUM(CR10:EC10) -> #REF!
